Workbook

Sheet 總表
A1: 20260428 | B1: 第一場 | K1: 客隊 | R1: 主場
B2: =J3 -> 06:10 | J2: 第一場 | K2: =數據分析!E3 -> 光芒 | R2: =數據分析!I3 -> 守護者 | Y2: -99 | Z2: -8.1 | AA2: 甜過頭
B3: =IF(K3<>"", K2&K1, IF(R3<>"", R2&R1, "")) -> 光芒客隊 | D3: 合理讓分 | E3: =IF(K3<>"", K2&"讓分", IF(R3<>"", R2&"讓分", "")) -> 光芒讓分 | G3: 金流 | H3: 合理性 | J3: =數據分析!C3 -> 06:10 | K3: =數據分析!F3 -> 0 | N3: =數據分析!G3 -> 0.31 | R3: =數據分析!J3 -> 1分贏 | U3: =數據分析!K3 -> 0.69 | Y3: -8 | Z3: -6.1 | AA3: 很甜
J4: =K2&"勝負" -> 光芒勝負 | L4: =數據分析!AE2 -> 3連勝 | M4: =數據分析!AB2 -> W.W.L.W.L.L.L.W.W.W | Q4: =R2&"勝負" -> 守護者勝負 | S4: =數據分析!AE3 -> 2連敗 | T4: =數據分析!AB3 -> L.W.L.W.W.L.W.W.L.L | Y4: -6 | Z4: -4.1 | AA4: 有點甜
B5: =ABS(L6-S6) -> 0.8 | D5: =IF(R3<>0, (B5*3.5)+3, B5*3.5) -> 5.8 | E5: {=IF(K3<>"", "讓" & (LEFT(K3, MIN(FIND({"分","贏","輸"},K3&"分贏輸"))-1) + IF(ISNUMBER(FIND("輸",K3)), 1, 0)), IF(R3<>"", "讓" & (LEFT(R3, MIN(FIND({"分","贏","輸"},R3&"分贏輸"))-1) + IF(ISNUMBER(FIND("輸",R3)), 1, 0)), "" ) )} -> 讓0 | G5: =IF(K3<>"", N3, IF(R3<>"", U3, "")) -> 0.31 | H5: =VLOOKUP(D5 - VALUE(SUBSTITUTE(E5,"讓","")), $Y$2:$AA$12, 3, TRUE) -> 硬 | J5: =K2&"過盤" -> 光芒過盤 | L5: =數據分析!X2 -> 3連O | M5: =數據分析!Y2 -> O.O.X.O.X.X.X.O.O.O | Q5: =R2&"過盤" -> 守護者過盤 | S5: =數據分析!X3 -> 2連X | T5: =數據分析!Y3 -> X.O.X.O.O.X.O.O.X.X | Y5: -4 | Z5: -2.1 | AA5: 甜
J6: =K2&"基本" -> 光芒基本 | L6: =數據分析!AH2 -> 4.8 | O6: =數據分析!AI2 -> B+ | Q6: =R2&"基本" -> 守護者基本 | S6: =數據分析!AH3 -> 4 | V6: =數據分析!AI3 -> B- | Y6: -2 | Z6: -1.1 | AA6: 稍微甜
J7: =$K$2&"進階" -> 光芒進階 | L7: =數據分析!AJ2 -> 4.25 | O7: =數據分析!AK2 -> B | Q7: =$R$2&"進階" -> 守護者進階 | S7: =數據分析!AJ3 -> 5.55 | V7: =數據分析!AK3 -> A | Y7: -1 | Z7: 1 | AA7: 合理
J8: =$K$2&"GP/出賽" -> 光芒GP/出賽 | L8: =數據分析!$CD$2 -> 27 | N8: =數據分析!$CD$3 -> 0 | O8: =L8-S8 -> -2 | Q8: =$R$2&"GP/出賽" -> 守護者GP/出賽 | S8: =數據分析!$CD$4 -> 29 | U8: =數據分析!$CD$5 -> 0 | V8: =S8-L8 -> 2 | Y8: 1.1 | Z8: 2 | AA8: 稍微硬
J9: =K2&"R/得分" -> 光芒R/得分 | L9: =數據分析!$CF$2 -> 132 | N9: =數據分析!$CF$3 -> 0.75 | O9: =L9-S9 -> 14 | Q9: =$R$2&"R/得分" -> 守護者R/得分 | S9: =數據分析!$CF$4 -> 118 | U9: =數據分析!$CF$5 -> 0.45 | V9: =S9-L9 -> -14 | Y9: 2.1 | Z9: 4 | AA9: 有點硬
J10: =$K$2&"H/安打" -> 光芒H/安打 | L10: =數據分析!$CG$2 -> 238 | N10: =數據分析!$CG$3 -> 0 | O10: =L10-S10 -> 19 | Q10: =$R$2&"H/安打" -> 守護者H/安打 | S10: =數據分析!$CG$4 -> 219 | U10: =數據分析!$CG$5 -> 0 | V10: =S10-L10 -> -19 | Y10: 4.1 | Z10: 6 | AA10: 硬
J11: =$K$2&"2B/二壘打" -> 光芒2B/二壘打 | L11: =數據分析!$CH$2 -> 38 | N11: =數據分析!$CH$3 -> 0 | O11: =L11-S11 -> -11 | Q11: =$R$2&"2B/二壘打" -> 守護者2B/二壘打 | S11: =數據分析!$CH$4 -> 49 | U11: =數據分析!$CH$5 -> 0 | V11: =S11-L11 -> 11 | Y11: 6.1 | Z11: 8 | AA11: 很硬
J12: =$K$2&"3B/三壘打" -> 光芒3B/三壘打 | L12: =數據分析!$CI$2 -> 5 | N12: =數據分析!$CI$3 -> 0 | O12: =L12-S12 -> 4 | Q12: =$R$2&"3B/3壘打" -> 守護者3B/3壘打 | S12: =數據分析!$CI$4 -> 1 | U12: =數據分析!$CI$5 -> 0 | V12: =S12-L12 -> -4 | Y12: 8.1 | Z12: 99 | AA12: 硬過頭
J13: =$K$2&"HR/全壘打" -> 光芒HR/全壘打 | L13: =數據分析!$CJ$2 -> 26 | N13: =數據分析!$CJ$3 -> 0.3 | O13: =L13-S13 -> -4 | Q13: =$R$2&"HR/全壘打" -> 守護者HR/全壘打 | S13: =數據分析!$CJ$4 -> 30 | U13: =數據分析!$CJ$5 -> 0.4 | V13: =S13-L13 -> 4
J14: =$K$2&"RBI/打點" -> 光芒RBI/打點 | L14: =數據分析!$CK$2 -> 126 | N14: =數據分析!$CK$3 -> 0.5 | O14: =L14-S14 -> 13 | Q14: =$R$2&"RBI/打點" -> 守護者RBI/打點 | S14: =數據分析!$CK$4 -> 113 | U14: =數據分析!$CK$5 -> 0.3 | V14: =S14-L14 -> -13
J15: =$K$2&"TB/壘打數" -> 光芒TB/壘打數 | L15: =數據分析!$CL$2 -> 364 | N15: =數據分析!$CL$3 -> 0 | O15: =L15-S15 -> 4 | Q15: =$R$2&"TB/壘打數" -> 守護者TB/壘打數 | S15: =數據分析!$CL$4 -> 360 | U15: =數據分析!$CL$5 -> 0 | V15: =S15-L15 -> -4
J16: =$K$2&"SB/盜壘" -> 光芒SB/盜壘 | L16: =數據分析!$CO$2 -> 29 | N16: =數據分析!$CO$3 -> 0.35 | O16: =L16-S16 -> 9 | Q16: =$R$2&"SB/盜壘" -> 守護者SB/盜壘 | S16: =數據分析!$CO$4 -> 20 | U16: =數據分析!$CO$5 -> 0.25 | V16: =S16-L16 -> -9
J17: =$K$2&"AVG/打擊率" -> 光芒AVG/打擊率 | L17: =數據分析!$CP$2 -> .258 | N17: =數據分析!$CR$3 -> 0.6 | O17: =L17-S17 -> 0.027 | Q17: =$R$2&"AVG/打擊率" -> 守護者AVG/打擊率 | S17: =數據分析!$CP$4 -> .231 | U17: =數據分析!$CR$5 -> 0.6 | V17: =S17-L17 -> -0.027
J18: =$K$2&"OBP/上壘率" -> 光芒OBP/上壘率 | L18: =數據分析!$CQ$2 -> .335 | N18: =數據分析!$CU$3 -> 0.9 | O18: =L18-S18 -> 0.016 | Q18: =$R$2&"OBP/上壘率" -> 守護者OBP/上壘率 | S18: =數據分析!$CQ$4 -> .319 | U18: =數據分析!$CU$5 -> 0.8 | V18: =S18-L18 -> -0.016
J19: =$K$2&"SLG/長打率" -> 光芒SLG/長打率 | L19: =數據分析!$CR$2 -> .394 | N19: =數據分析!$CX$3 -> 0 | O19: =L19-S19 -> 0.014 | Q19: =$R$2&"SLG/長打率" -> 守護者SLG/長打率 | S19: =數據分析!$CR$4 -> .380 | U19: =數據分析!$CX$5 -> 0 | V19: =S19-L19 -> -0.014
J20: =$K$2&"保送" -> 光芒保送 | L20: =數據分析!$CM$2 -> 95 | N20: =數據分析!$CY$3 -> 0.6 | O20: =L20-S20 -> -19 | Q20: =$R$2&"保送" -> 守護者保送 | S20: =數據分析!$CM$4 -> 114 | U20: =數據分析!$CY$5 -> 0.8 | V20: =S20-L20 -> 19
J21: =$K$2&"三振" -> 光芒三振 | L21: =數據分析!$CN$2 -> 191 | N21: =數據分析!$CZ$3 -> 0.6 | O21: =L21-S21 -> -37 | Q21: =$R$2&"三振" -> 守護者三振 | S21: =數據分析!$CN$4 -> 228 | U21: =數據分析!$CZ$5 -> 0.75 | V21: =S21-L21 -> 37
J22: =K2&"投手" -> 光芒投手 | L22: =先發名單!E2 -> Steven Matz | Q22: =R2&"投手" -> 守護者投手 | S22: =先發名單!F2 -> Parker Messick
J23: ERA | Q23: ERA | X23: =K2&"先發" -> 光芒先發 | Z23: 戰力 | AC23: 命中率 | AE23: =R2&"先發" -> 守護者先發 | AG23: 戰力 | AJ23: 命中率
J24: WHIP | Q24: WHIP | X24: =數據分析!DF2 -> Yandy Diaz | Z24: =數據分析!DH3 -> 2.8 | AB24: =Z24-AG24 -> #VALUE! | AC24: =數據分析!DI3 -> 5 | AE24: =數據分析!EI2 -> Taylor Walls | AG24: =數據分析!EK3 -> #VALUE! | AI24: =AG24-Z24 -> #VALUE! | AJ24: =數據分析!EL3 -> #VALUE!
J25: IP | Q25: IP | X25: =數據分析!DF4 -> J. Aranda | Z25: =數據分析!DH5 -> #VALUE! | AB25: =Z25-AG25 -> #VALUE! | AC25: =數據分析!DI5 -> #VALUE! | AE25: =數據分析!EI4 -> Steven Kwan | AG25: =數據分析!EK5 -> 1.45 | AI25: =AG25-Z25 -> #VALUE! | AJ25: =數據分析!EL5 -> #N/A
J26: H | Q26: H | X26: =數據分析!DF6 -> J. Caminero | Z26: =數據分析!DH7 -> #VALUE! | AB26: =Z26-AG26 -> #VALUE! | AC26: =數據分析!DI7 -> #VALUE! | AE26: =數據分析!EI6 -> A. Martinez | AG26: =數據分析!EK7 -> #VALUE! | AI26: =AG26-Z26 -> #VALUE! | AJ26: =數據分析!EL7 -> #VALUE!
J27: K | Q27: K | X27: =數據分析!DF8 -> Ryan Vilade | Z27: =數據分析!DH9 -> 0.8 | AB27: =Z27-AG27 -> -2.7 | AC27: =數據分析!DI9 -> 5 | AE27: =數據分析!EI8 -> Jose Ramirez | AG27: =數據分析!EK9 -> 3.5 | AI27: =AG27-Z27 -> 2.7 | AJ27: =數據分析!EL9 -> 5
J28: BB | Q28: BB | X28: =數據分析!DF10 -> Jonny DeLuca | Z28: =數據分析!DH11 -> 2.8 | AB28: =Z28-AG28 -> 0.8 | AC28: =數據分析!DI11 -> 5 | AE28: =數據分析!EI10 -> Rhys Hoskins | AG28: =數據分析!EK11 -> 2 | AI28: =AG28-Z28 -> -0.8 | AJ28: =數據分析!EL11 -> #N/A
J29: HR | Q29: HR | Z29: =Z24+Z25+Z26+Z27+Z28 -> #VALUE! | AB29: =Z29-AG29 -> #VALUE! | AC29: =AC24+AC25+AC26+AC27+AC28 -> #VALUE! | AG29: =AG24+AG25+AG26+AG27+AG28 -> #VALUE! | AI29: =AG29-Z29 -> #VALUE! | AJ29: =AJ24+AJ25+AJ26+AJ27+AJ28 -> #VALUE!
L30: 打擊率 | M30: 打數-安打 | N30: 上壘率 | O30: 全壘打 | P30: 長打率
J31: =先發名單!G2 -> Yandy Diaz | X31: =K2&"板凳" -> 光芒板凳 | Z31: 戰力 | AC31: 命中率 | AE31: =R2&"板凳" -> 守護者板凳 | AG31: 戰力 | AJ31: 命中率
J32: =先發名單!H3 -> Ivan Herrera | X32: =數據分析!DF12 -> B. Williamson | Z32: =數據分析!DH13 -> #VALUE! | AB32: =Z32-AG32 -> #VALUE! | AC32: =數據分析!DI13 -> #VALUE! | AE32: =數據分析!EI12 -> David Fry | AG32: =數據分析!EK13 -> 0.6 | AI32: =AG32-Z32 -> #VALUE! | AJ32: =數據分析!EL13 -> 5
X33: =數據分析!DF14 -> C. Simpson | Z33: =數據分析!DH15 -> #VALUE! | AB33: =Z33-AG33 -> #VALUE! | AC33: =數據分析!DI15 -> #VALUE! | AE33: =數據分析!EI14 -> D. Schneemann | AG33: =數據分析!EK15 -> #VALUE! | AI33: =AG33-Z33 -> #VALUE! | AJ33: =數據分析!EL15 -> #VALUE!
X34: =數據分析!DF16 -> Nick Fortes | Z34: =數據分析!DH17 -> 1.95 | AB34: =Z34-AG34 -> 0.9 | AC34: =數據分析!DI17 -> 5 | AE34: =數據分析!EI16 -> Juan Brito | AG34: =數據分析!EK17 -> 1.05 | AI34: =AG34-Z34 -> -0.9 | AJ34: =數據分析!EL17 -> #N/A
X35: =數據分析!DF18 -> Taylor Walls | Z35: =數據分析!DH19 -> 0.75 | AB35: =Z35-AG35 -> #VALUE! | AC35: =數據分析!DI19 -> 5 | AE35: =數據分析!EI18 -> A. Hedges | AG35: =數據分析!EK19 -> #VALUE! | AI35: =AG35-Z35 -> #VALUE! | AJ35: =數據分析!EL19 -> #VALUE!
X36: =數據分析!DF20 -> 0 | Z36: =數據分析!DH21 -> 0 | AB36: =Z36-AG36 -> #VALUE! | AC36: =數據分析!DI21 -> 0 | AE36: =數據分析!EI20 -> B. Rocchio | AG36: =數據分析!EK21 -> #VALUE! | AI36: =AG36-Z36 -> #VALUE! | AJ36: =數據分析!EL21 -> #VALUE!
X37: =數據分析!DF22 -> 0 | Z37: =數據分析!DH23 -> 0 | AB37: =Z37-AG37 -> #VALUE! | AC37: =數據分析!DI23 -> 0 | AE37: =數據分析!EI22 -> 0 | AG37: =數據分析!EK23 -> #VALUE! | AI37: =AG37-Z37 -> #VALUE! | AJ37: =數據分析!EL23 -> #VALUE!
X38: =數據分析!DF24 -> 0 | Z38: =數據分析!DH25 -> 0 | AB38: =Z38-AG38 -> #VALUE! | AC38: =數據分析!DI25 -> 0 | AE38: =數據分析!EI24 -> 0 | AG38: =數據分析!EK25 -> #VALUE! | AI38: =AG38-Z38 -> #VALUE! | AJ38: =數據分析!EL25 -> #VALUE!
X39: =數據分析!DF26 -> 0 | Z39: =數據分析!DH27 -> 0 | AB39: =Z39-AG39 -> #VALUE! | AC39: =數據分析!DI27 -> 0 | AE39: =數據分析!EI26 -> 0 | AG39: =數據分析!EK27 -> #VALUE! | AI39: =AG39-Z39 -> #VALUE! | AJ39: =數據分析!EL27 -> #VALUE!
Z40: =Z35+Z36+Z37+Z38+Z39 -> 0.75 | AB40: =Z40-AG40 -> #VALUE! | AC40: =AC35+AC36+AC37+AC38+AC39 -> 5 | AG40: =AG35+AG36+AG37+AG38+AG39 -> #VALUE! | AI40: =AG40-Z40 -> #VALUE! | AJ40: =AJ35+AJ36+AJ37+AJ38+AJ39 -> #VALUE!
...

Sheet 數據分析
A1: =總表!A1 -> 20260428 | AG1: GP/出賽 | AH1: 整體平均 | AJ1: 攻擊力 | AL1: AB/打數 | AM1: R/得分 | AN1: H/安打 | AO1: 2B/二壘打 | AP1: 3B/三壘打 | AQ1: HR/全壘打 | AR1: RBI/打點 | AS1: TB/壘打數 | AT1: BB/保送 | AU1: SO/三振 | AV1: SB/盜壘 | AW1: AVG/打擊率 | AX1: OBP/上壘率 | AY1: SLG/長打率 | AZ1: OPS/整體攻擊指數 | BA1: WAR/勝場貢獻值 | BB1: RC/得分創造 | BC1: RC/27/每27出局得分創造 | BD1: BB/PA/保送率 | BE1: BB/K/保送三振比 | BF1: ISOP/純長打率 | BG1: SECA/次級攻擊指數 | BH1: P/PA/每打席用球數 | BI1: XBH/長打數 | BJ1: PA/打席 | BK1: AB/HR/全壘打打數比 | BM1: AVG/打擊率 | BO1: 0.1 | BP1: OBP/上壘率 | BR1: 0.2 | BS1: SLG/長打率 | BU1: 0.2 | BV1: R/G每場得分 | BX1: 0.15 | BY1: RBI/每場打點 | CA1: 0.1 | CD1: GP/出賽 | CE1: AB/打數 | CF1: R/得分 | CG1: H/安打 | CH1: 2B/二壘打 | CI1: 3B/三壘打 | CJ1: HR/全壘打 | CK1: RBI/打點 | CL1: TB/壘打數 | CM1: BB/保送 | CN1: SO/三振 | CO1: SB/盜壘 | CP1: AVG/打擊率 | CQ1: OBP/上壘率 | CR1: SLG/長打率 | CS1: OPS/整體攻擊指數 | CT1: WAR/勝場貢獻值 | CU1: RC/得分創造 | CV1: RC/27/每27出局得分創造 | CW1: BB/PA/保送率 | CX1: BB/K/保送三振比 | CY1: ISOP/純長打率 | CZ1: SECA/次級攻擊指數 | DA1: P/PA/每打席用球數 | DB1: XBH/長打數 | DC1: PA/打席 | DD1: AB/HR/全壘打打數比 | DF1: =CB2 -> 光芒 | DG1: GP/出賽 | DH1: AB/打數 | DI1: R/得分 | DJ1: H/安打 | DK1: 2B/二壘打 | DL1: 3B/三壘打 | DM1: HR/全壘打 | DN1: RBI/打點 | DO1: TB/壘打數 | DP1: BB/保送 | DQ1: SO/三振 | DR1: SB/盜壘 | DS1: AVG/打擊率 | DT1: OBP/上壘率 | DU1: SLG/長打率 | DV1: OPS/整體攻擊指數 | DW1: WAR/勝場貢獻值 | DX1: RC/得分創造 | DY1: RC/27/每27出局得分創造 | DZ1: BB/PA/保送率 | EA1: BB/K/保送三振比 | EB1: ISOP/純長打率 | EC1: SECA/次級攻擊指數 | ED1: P/PA/每打席用球數 | EE1: XBH/長打數 | EF1: PA/打席 | EG1: AB/HR/全壘打打數比 | EI1: =CB4 -> 守護者 | EJ1: GP/出賽 | EK1: AB/打數 | EL1: R/得分 | EM1: H/安打 | EN1: 2B/二壘打 | EO1: 3B/三壘打 | EP1: HR/全壘打 | EQ1: RBI/打點 | ER1: TB/壘打數 | ES1: BB/保送 | ET1: SO/三振 | EU1: SB/盜壘 | EV1: AVG/打擊率 | EW1: OBP/上壘率 | EX1: SLG/長打率 | EY1: OPS/整體攻擊指數 | EZ1: WAR/勝場貢獻值 | FA1: RC/得分創造 | FB1: RC/27/每27出局得分創造 | FC1: BB/PA/保送率 | FD1: BB/K/保送三振比 | FE1: ISOP/純長打率 | FF1: SECA/次級攻擊指數 | FG1: P/PA/每打席用球數 | FH1: XBH/長打數 | FI1: PA/打席 | FJ1: AB/HR/全壘打打數比 | FK1: PTS/得分 | FM1: 0.25 | FN1: REB/籃板 | FP1: 0.15 | FQ1: AST/助攻 | FS1: 0.1 | FT1: STL/抄截 | FV1: 0.1 | FW1: BLK/阻攻 | FY1: 0.05
B2: 日期 | C2: 時間 | D2: 結果 | E2: 客隊 | F2: 讓分 | G2: 比例 | H2: 結果 | I2: 主隊 | J2: 讓分 | K2: 比例 | L2: =TEXT(DATE(LEFT($A1,4), MID($A1,5,2), RIGHT($A1,2))-10, "m/d") -> 4/18 | M2: =TEXT(DATE(LEFT($A1,4), MID($A1,5,2), RIGHT($A1,2))-9, "m/d") -> 4/19 | N2: =TEXT(DATE(LEFT($A1,4), MID($A1,5,2), RIGHT($A1,2))-8, "m/d") -> 4/20 | O2: =TEXT(DATE(LEFT($A1,4), MID($A1,5,2), RIGHT($A1,2))-7, "m/d") -> 4/21 | P2: =TEXT(DATE(LEFT($A1,4), MID($A1,5,2), RIGHT($A1,2))-6, "m/d") -> 4/22 | Q2: =TEXT(DATE(LEFT($A1,4), MID($A1,5,2), RIGHT($A1,2))-5, "m/d") -> 4/23 | R2: =TEXT(DATE(LEFT(A1,4), MID(A1,5,2), RIGHT(A1,2))-4, "m/d") -> 4/24 | S2: =TEXT(DATE(LEFT(A1,4), MID(A1,5,2), RIGHT(A1,2))-3, "m/d") -> 4/25 | T2: =TEXT(DATE(LEFT(A1,4), MID(A1,5,2), RIGHT(A1,2))-2, "m/d") -> 4/26 | U2: =TEXT(DATE(LEFT(A1,4), MID(A1,5,2), RIGHT(A1,2))-1, "m/d") -> 4/27 | V2: =C3 -> 06:10 | W2: =E3 -> 光芒 | X2: {=_xlfn.LET(_xlpm.s,SUBSTITUTE(Y2,".",""),_xlpm.c,RIGHT(_xlpm.s,1),_xlpm.n,ROW(INDIRECT("1:"&LEN(_xlpm.s))),_xlpm.cnt,MAX(IF(RIGHT(_xlpm.s,_xlpm.n)=REPT(_xlpm.c,_xlpm.n),_xlpm.n,0)),IF(_xlpm.cnt>=2,_xlpm.cnt&"連"&_xlpm.c,"1"&_xlpm.c))} -> 3連O | Y2: {=INDEX(各隊正負!$F:$F, MATCH("*"&$W2&"*", 各隊正負!$A:$A, 0)+6)} -> O.O.X.O.X.X.X.O.O.O | AB2: {=INDEX(各隊正負!$F:$F, MATCH("*"&$W2&"*", 各隊正負!$A:$A, 0)+4)} -> W.W.L.W.L.L.L.W.W.W | AE2: {=_xlfn.LET(_xlpm.s,SUBSTITUTE(AB2,".",""),_xlpm.c,RIGHT(_xlpm.s,1),_xlpm.n,ROW(INDIRECT("1:"&LEN(_xlpm.s))),_xlpm.cnt,MAX(IF(RIGHT(_xlpm.s,_xlpm.n)=REPT(_xlpm.c,_xlpm.n),_xlpm.n,0)),_xlpm.suffix,IF(_xlpm.c="W","勝","敗"),IF(_xlpm.cnt>=2,_xlpm.cnt&"連"&_xlpm.suffix,"1"&_xlpm.suffix))} -> 3連勝 | AF2: =E3 -> 光芒 | AG2: {=IFERROR(INDEX(各隊total!$B:$AB, MATCH($AF2, 各隊total!$A:$A, 0), COLUMN(A1)), "")} -> 27 | AH2: =CB3 -> 4.8 | AI2: =VLOOKUP(AH2*1, BV$15:BX$25, 3, TRUE) -> B+ | AJ2: =CC3 -> 4.25 | AK2: =VLOOKUP(AJ2*1, BY$15:CA$25, 3, TRUE) -> B | AL2: {=IFERROR(INDEX(各隊total!$C:$AB, MATCH($AF2, 各隊total!$A:$A, 0), COLUMN(A1)), "")} -> 923 | AM2: {=IFERROR(INDEX(各隊total!$D:$AB, MATCH($AF2, 各隊total!$A:$A, 0), COLUMN(A1)), "")} -> 132 | AN2: {=IFERROR(INDEX(各隊total!$E:$AB, MATCH($AF2, 各隊total!$A:$A, 0), COLUMN(A1)), "")} -> 238 | AO2: {=IFERROR(INDEX(各隊total!$F:$AB, MATCH($AF2, 各隊total!$A:$A, 0), COLUMN(A1)), "")} -> 38 | AP2: {=IFERROR(INDEX(各隊total!$G:$AB, MATCH($AF2, 各隊total!$A:$A, 0), COLUMN(A1)), "")} -> 5 | AQ2: {=IFERROR(INDEX(各隊total!$H:$AB, MATCH($AF2, 各隊total!$A:$A, 0), COLUMN(A1)), "")} -> 26 | AR2: {=IFERROR(INDEX(各隊total!$I:$AB, MATCH($AF2, 各隊total!$A:$A, 0), COLUMN(A1)), "")} -> 126 | AS2: {=IFERROR(INDEX(各隊total!$J:$AB, MATCH($AF2, 各隊total!$A:$A, 0), COLUMN(A1)), "")} -> 364 | AT2: {=IFERROR(INDEX(各隊total!$K:$AB, MATCH($AF2, 各隊total!$A:$A, 0), COLUMN(A1)), "")} -> 95 | AU2: {=IFERROR(INDEX(各隊total!$L:$AB, MATCH($AF2, 各隊total!$A:$A, 0), COLUMN(A1)), "")} -> 191 | AV2: {=IFERROR(INDEX(各隊total!$M:$AB, MATCH($AF2, 各隊total!$A:$A, 0), COLUMN(A1)), "")} -> 29 | AW2: {=IFERROR(INDEX(各隊total!$N:$AB, MATCH($AF2, 各隊total!$A:$A, 0), COLUMN(A1)), "")} -> .258 | AX2: {=IFERROR(INDEX(各隊total!$O:$AB, MATCH($AF2, 各隊total!$A:$A, 0), COLUMN(A1)), "")} -> .335 | AY2: {=IFERROR(INDEX(各隊total!$P:$AB, MATCH($AF2, 各隊total!$A:$A, 0), COLUMN(A1)), "")} -> .394 | AZ2: {=IFERROR(INDEX(各隊total!$Q:$AB, MATCH($AF2, 各隊total!$A:$A, 0), COLUMN(A1)), "")} -> .729 | BA2: {=IFERROR(INDEX(各隊total!$R:$AB, MATCH($AF2, 各隊total!$A:$A, 0), COLUMN(A1)), "")} -> 0 | BB2: {=IFERROR(INDEX(各隊total!$S:$AB, MATCH($AF2, 各隊total!$A:$A, 0), COLUMN(A1)), "")} -> 126.2 | BC2: {=IFERROR(INDEX(各隊total!$T:$AB, MATCH($AF2, 各隊total!$A:$A, 0), COLUMN(A1)), "")} -> 4.7 | BD2: {=IFERROR(INDEX(各隊total!$U:$AB, MATCH($AF2, 各隊total!$A:$A, 0), COLUMN(A1)), "")} -> .090 | BE2: {=IFERROR(INDEX(各隊total!$V:$AB, MATCH($AF2, 各隊total!$A:$A, 0), COLUMN(A1)), "")} -> 0.50 | BF2: {=IFERROR(INDEX(各隊total!$W:$AB, MATCH($AF2, 各隊total!$A:$A, 0), COLUMN(A1)), "")} -> .137 | BG2: {=IFERROR(INDEX(各隊total!$X:$AB, MATCH($AF2, 各隊total!$A:$A, 0), COLUMN(A1)), "")} -> .261 | BH2: {=IFERROR(INDEX(各隊total!$Y:$AB, MATCH($AF2, 各隊total!$A:$A, 0), COLUMN(A1)), "")} -> 3.80 | BI2: {=IFERROR(INDEX(各隊total!$Z:$AB, MATCH($AF2, 各隊total!$A:$A, 0), COLUMN(A1)), "")} -> 69 | BJ2: {=IFERROR(INDEX(各隊total!$AA:$AB, MATCH($AF2, 各隊total!$A:$A, 0), COLUMN(A1)), "")} -> 1051 | BK2: {=IFERROR(INDEX(各隊total!$AB:$AB, MATCH($AF2, 各隊total!$A:$A, 0), COLUMN(A1)), "")} -> 35.5 | BL2: {=IFERROR(INDEX(各隊total!$C:$AB, MATCH($AF2, 各隊total!$A:$A, 0), COLUMN(AA1)), "")} | BM2: 0 | BN2: 0.18 | BO2: 0 | BP2: 0 | BQ2: 0.25 | BR2: 0 | BS2: 0 | BT2: 0.31 | BU2: 0 | BV2: 0 | BW2: 3 | BX2: 0 | BY2: 0 | BZ2: 2.8 | CA2: 0 | CB2: =AF2 -> 光芒 | CD2: =AG2 -> 27 | CE2: =AL2 -> 923 | CF2: =AM2 -> 132 | CG2: =AN2 -> 238 | CH2: =AO2 -> 38 | CI2: =AP2 -> 5 | CJ2: =AQ2 -> 26 | CK2: =AR2 -> 126 | CL2: =AS2 -> 364 | ... DD2: =BK2 -> 35.5 | DF2: =先發名單!G$2 -> Yandy Diaz | DG2: {=IFERROR(INDEX(球員狀態!$C$2:$C$5000, MATCH(1, (球員狀態!$A$2:$A$5000=$DF$1)*(ISNUMBER(SEARCH($DF2, 球員狀態!$B$2:$B$5000))), 0)), "")} -> 1B | DJ2: {=IFERROR(INDEX(球員狀態!$F$2:$F$5000, MATCH(1, (球員狀態!$A$2:$A$5000=$DF$1)*(ISNUMBER(SEARCH($DF2, 球員狀態!$B$2:$B$5000))), 0)), "")} -> 16 | DK2: {=IFERROR(INDEX(球員狀態!G$2:G$5000, MATCH(1, (球員狀態!$A$2:$A$5000=$DF$1)*(ISNUMBER(SEARCH($DF2, 球員狀態!$B$2:$B$5000))), 0)), "")} -> 35 | DL2: {=IFERROR(INDEX(球員狀態!H$2:H$5000, MATCH(1, (球員狀態!$A$2:$A$5000=$DF$1)*(ISNUMBER(SEARCH($DF2, 球員狀態!$B$2:$B$5000))), 0)), "")} -> 3 | DM2: {=IFERROR(INDEX(球員狀態!I$2:I$5000, MATCH(1, (球員狀態!$A$2:$A$5000=$DF$1)*(ISNUMBER(SEARCH($DF2, 球員狀態!$B$2:$B$5000))), 0)), "")} -> 1 | DN2: {=IFERROR(INDEX(球員狀態!J$2:J$5000, MATCH(1, (球員狀態!$A$2:$A$5000=$DF$1)*(ISNUMBER(SEARCH($DF2, 球員狀態!$B$2:$B$5000))), 0)), "")} -> 4 | DO2: {=IFERROR(INDEX(球員狀態!K$2:K$5000, MATCH(1, (球員狀態!$A$2:$A$5000=$DF$1)*(ISNUMBER(SEARCH($DF2, 球員狀態!$B$2:$B$5000))), 0)), "")} -> 20 | DP2: {=IFERROR(INDEX(球員狀態!L$2:L$5000, MATCH(1, (球員狀態!$A$2:$A$5000=$DF$1)*(ISNUMBER(SEARCH($DF2, 球員狀態!$B$2:$B$5000))), 0)), "")} -> 52 | DQ2: {=IFERROR(INDEX(球員狀態!M$2:M$5000, MATCH(1, (球員狀態!$A$2:$A$5000=$DF$1)*(ISNUMBER(SEARCH($DF2, 球員狀態!$B$2:$B$5000))), 0)), "")} -> 11 | DR2: {=IFERROR(INDEX(球員狀態!N$2:N$5000, MATCH(1, (球員狀態!$A$2:$A$5000=$DF$1)*(ISNUMBER(SEARCH($DF2, 球員狀態!$B$2:$B$5000))), 0)), "")} -> 14 | ... EF2: {=IFERROR(INDEX(球員狀態!AB$2:AB$5000, MATCH(1, (球員狀態!$A$2:$A$5000=$DF$1)*(ISNUMBER(SEARCH($DF2, 球員狀態!$B$2:$B$5000))), 0)), "")} -> 8 | EI2: =先發名單!O$2 -> Taylor Walls | EJ2: {=IFERROR(INDEX(球員狀態!$C$2:$C$5000, MATCH(1, (球員狀態!$A$2:$A$5000=$EI$1)*(ISNUMBER(SEARCH($EI2, 球員狀態!$B$2:$B$5000))), 0)), "")} | EM2: {=IFERROR(INDEX(球員狀態!F$2:F$5000, MATCH(1, (球員狀態!$A$2:$A$5000=$EI$1)*(ISNUMBER(SEARCH($EI2, 球員狀態!$B$2:$B$5000))), 0)), "")} | EN2: {=IFERROR(INDEX(球員狀態!G$2:G$5000, MATCH(1, (球員狀態!$A$2:$A$5000=$EI$1)*(ISNUMBER(SEARCH($EI2, 球員狀態!$B$2:$B$5000))), 0)), "")} | EO2: {=IFERROR(INDEX(球員狀態!H$2:H$5000, MATCH(1, (球員狀態!$A$2:$A$5000=$EI$1)*(ISNUMBER(SEARCH($EI2, 球員狀態!$B$2:$B$5000))), 0)), "")} | EP2: {=IFERROR(INDEX(球員狀態!I$2:I$5000, MATCH(1, (球員狀態!$A$2:$A$5000=$EI$1)*(ISNUMBER(SEARCH($EI2, 球員狀態!$B$2:$B$5000))), 0)), "")} | EQ2: {=IFERROR(INDEX(球員狀態!J$2:J$5000, MATCH(1, (球員狀態!$A$2:$A$5000=$EI$1)*(ISNUMBER(SEARCH($EI2, 球員狀態!$B$2:$B$5000))), 0)), "")} | ER2: {=IFERROR(INDEX(球員狀態!K$2:K$5000, MATCH(1, (球員狀態!$A$2:$A$5000=$EI$1)*(ISNUMBER(SEARCH($EI2, 球員狀態!$B$2:$B$5000))), 0)), "")} | ES2: {=IFERROR(INDEX(球員狀態!L$2:L$5000, MATCH(1, (球員狀態!$A$2:$A$5000=$EI$1)*(ISNUMBER(SEARCH($EI2, 球員狀態!$B$2:$B$5000))), 0)), "")} | ET2: {=IFERROR(INDEX(球員狀態!M$2:M$5000, MATCH(1, (球員狀態!$A$2:$A$5000=$EI$1)*(ISNUMBER(SEARCH($EI2, 球員狀態!$B$2:$B$5000))), 0)), "")} | ... FI2: {=IFERROR(INDEX(球員狀態!AB$2:AB$5000, MATCH(1, (球員狀態!$A$2:$A$5000=$EI$1)*(ISNUMBER(SEARCH($EI2, 球員狀態!$B$2:$B$5000))), 0)), "")} | FK2: 0 | FL2: 3 | FM2: 0 | FN2: 0 | FO2: 1.5 | FP2: 0 | FQ2: 0 | FR2: 1.2 | FS2: 0 | FT2: 0 | FU2: 0.3 | FV2: 0 | FW2: 0 | FX2: 0.2 | FY2: 0
A3: 1 | B3: {=_xlfn._xlws.FILTER(每日數據!A:J, 每日數據!A:A=$A$1&"", "")} -> 20260428 | C3: 06:10 | D3: 0 | E3: 光芒 | F3: 0 | G3: 0.31 | H3: 0 | I3: 守護者 | J3: 1分贏 | K3: 0.69 | L3: {=_xlfn.LET(_xlpm.d,DATE(VALUE(LEFT($A$1,4)),VALUE(MID($A$1,5,2)),VALUE(RIGHT($A$1,2))),INDEX(正負盤!$5:$5,MATCH(1,(MONTH(正負盤!$4:$4)=MONTH(_xlpm.d-2))*(DAY(正負盤!$4:$4)=DAY(_xlpm.d-10)),0)))} -> 六 | M3: {=_xlfn.LET(_xlpm.d,DATE(VALUE(LEFT($A$1,4)),VALUE(MID($A$1,5,2)),VALUE(RIGHT($A$1,2))),INDEX(正負盤!$5:$5,MATCH(1,(MONTH(正負盤!$4:$4)=MONTH(_xlpm.d-2))*(DAY(正負盤!$4:$4)=DAY(_xlpm.d-9)),0)))} -> 日 | N3: {=_xlfn.LET(_xlpm.d,DATE(VALUE(LEFT($A$1,4)),VALUE(MID($A$1,5,2)),VALUE(RIGHT($A$1,2))),INDEX(正負盤!$5:$5,MATCH(1,(MONTH(正負盤!$4:$4)=MONTH(_xlpm.d-2))*(DAY(正負盤!$4:$4)=DAY(_xlpm.d-8)),0)))} -> 一 | O3: {=_xlfn.LET(_xlpm.d,DATE(VALUE(LEFT($A$1,4)),VALUE(MID($A$1,5,2)),VALUE(RIGHT($A$1,2))),INDEX(正負盤!$5:$5,MATCH(1,(MONTH(正負盤!$4:$4)=MONTH(_xlpm.d-2))*(DAY(正負盤!$4:$4)=DAY(_xlpm.d-7)),0)))} -> 二 | P3: {=_xlfn.LET(_xlpm.d,DATE(VALUE(LEFT($A$1,4)),VALUE(MID($A$1,5,2)),VALUE(RIGHT($A$1,2))),INDEX(正負盤!$5:$5,MATCH(1,(MONTH(正負盤!$4:$4)=MONTH(_xlpm.d-2))*(DAY(正負盤!$4:$4)=DAY(_xlpm.d-6)),0)))} -> 三 | Q3: {=_xlfn.LET(_xlpm.d,DATE(VALUE(LEFT($A$1,4)),VALUE(MID($A$1,5,2)),VALUE(RIGHT($A$1,2))),INDEX(正負盤!$5:$5,MATCH(1,(MONTH(正負盤!$4:$4)=MONTH(_xlpm.d-2))*(DAY(正負盤!$4:$4)=DAY(_xlpm.d-5)),0)))} -> 四 | R3: {=_xlfn.LET(_xlpm.d,DATE(VALUE(LEFT($A$1,4)),VALUE(MID($A$1,5,2)),VALUE(RIGHT($A$1,2))),INDEX(正負盤!$5:$5,MATCH(1,(MONTH(正負盤!$4:$4)=MONTH(_xlpm.d-2))*(DAY(正負盤!$4:$4)=DAY(_xlpm.d-4)),0)))} -> 五 | S3: {=_xlfn.LET(_xlpm.d,DATE(VALUE(LEFT($A$1,4)),VALUE(MID($A$1,5,2)),VALUE(RIGHT($A$1,2))),INDEX(正負盤!$5:$5,MATCH(1,(MONTH(正負盤!$4:$4)=MONTH(_xlpm.d-2))*(DAY(正負盤!$4:$4)=DAY(_xlpm.d-3)),0)))} -> 六 | T3: {=_xlfn.LET(_xlpm.d,DATE(VALUE(LEFT($A$1,4)),VALUE(MID($A$1,5,2)),VALUE(RIGHT($A$1,2))),INDEX(正負盤!$5:$5,MATCH(1,(MONTH(正負盤!$4:$4)=MONTH(_xlpm.d-2))*(DAY(正負盤!$4:$4)=DAY(_xlpm.d-2)),0)))} -> 日 | U3: {=_xlfn.LET(_xlpm.d,DATE(VALUE(LEFT($A$1,4)),VALUE(MID($A$1,5,2)),VALUE(RIGHT($A$1,2))),INDEX(正負盤!$5:$5,MATCH(1,(MONTH(正負盤!$4:$4)=MONTH(_xlpm.d-1))*(DAY(正負盤!$4:$4)=DAY(_xlpm.d-1)),0)))} -> 一 | W3: =I3 -> 守護者 | X3: {=_xlfn.LET(_xlpm.s,SUBSTITUTE(Y3,".",""),_xlpm.c,RIGHT(_xlpm.s,1),_xlpm.n,ROW(INDIRECT("1:"&LEN(_xlpm.s))),_xlpm.cnt,MAX(IF(RIGHT(_xlpm.s,_xlpm.n)=REPT(_xlpm.c,_xlpm.n),_xlpm.n,0)),IF(_xlpm.cnt>=2,_xlpm.cnt&"連"&_xlpm.c,"1"&_xlpm.c))} -> 2連X | Y3: {=INDEX(各隊正負!$F:$F, MATCH("*"&$W3&"*", 各隊正負!$A:$A, 0)+6)} -> X.O.X.O.O.X.O.O.X.X | AB3: {=INDEX(各隊正負!$F:$F, MATCH("*"&$W3&"*", 各隊正負!$A:$A, 0)+4)} -> L.W.L.W.W.L.W.W.L.L | AE3: {=_xlfn.LET(_xlpm.s,SUBSTITUTE(AB3,".",""),_xlpm.c,RIGHT(_xlpm.s,1),_xlpm.n,ROW(INDIRECT("1:"&LEN(_xlpm.s))),_xlpm.cnt,MAX(IF(RIGHT(_xlpm.s,_xlpm.n)=REPT(_xlpm.c,_xlpm.n),_xlpm.n,0)),_xlpm.suffix,IF(_xlpm.c="W","勝","敗"),IF(_xlpm.cnt>=2,_xlpm.cnt&"連"&_xlpm.suffix,"1"&_xlpm.suffix))} -> 2連敗 | AF3: =I3 -> 守護者 | AG3: {=IFERROR(INDEX(各隊total!$B:$AB, MATCH($AF3, 各隊total!$A:$A, 0), COLUMN(A2)), "")} -> 29 | AH3: =CB5 -> 4 | AI3: =VLOOKUP(AH3*1, BV$15:BX$25, 3, TRUE) -> B- | AJ3: =CC5 -> 5.55 | AK3: =VLOOKUP(AJ3*1, BY$15:CA$25, 3, TRUE) -> A | AL3: {=IFERROR(INDEX(各隊total!$C:$AB, MATCH($AF3, 各隊total!$A:$A, 0), COLUMN(A2)), "")} -> 947 | AM3: {=IFERROR(INDEX(各隊total!$D:$AB, MATCH($AF3, 各隊total!$A:$A, 0), COLUMN(A2)), "")} -> 118 | AN3: {=IFERROR(INDEX(各隊total!$E:$AB, MATCH($AF3, 各隊total!$A:$A, 0), COLUMN(A2)), "")} -> 219 | AO3: {=IFERROR(INDEX(各隊total!$F:$AB, MATCH($AF3, 各隊total!$A:$A, 0), COLUMN(A2)), "")} -> 49 | AP3: {=IFERROR(INDEX(各隊total!$G:$AB, MATCH($AF3, 各隊total!$A:$A, 0), COLUMN(A2)), "")} -> 1 | AQ3: {=IFERROR(INDEX(各隊total!$H:$AB, MATCH($AF3, 各隊total!$A:$A, 0), COLUMN(A2)), "")} -> 30 | AR3: {=IFERROR(INDEX(各隊total!$I:$AB, MATCH($AF3, 各隊total!$A:$A, 0), COLUMN(A2)), "")} -> 113 | AS3: {=IFERROR(INDEX(各隊total!$J:$AB, MATCH($AF3, 各隊total!$A:$A, 0), COLUMN(A2)), "")} -> 360 | AT3: {=IFERROR(INDEX(各隊total!$K:$AB, MATCH($AF3, 各隊total!$A:$A, 0), COLUMN(A2)), "")} -> 114 | AU3: {=IFERROR(INDEX(各隊total!$L:$AB, MATCH($AF3, 各隊total!$A:$A, 0), COLUMN(A2)), "")} -> 228 | AV3: {=IFERROR(INDEX(各隊total!$M:$AB, MATCH($AF3, 各隊total!$A:$A, 0), COLUMN(A2)), "")} -> 20 | AW3: {=IFERROR(INDEX(各隊total!$N:$AB, MATCH($AF3, 各隊total!$A:$A, 0), COLUMN(A2)), "")} -> .231 | AX3: {=IFERROR(INDEX(各隊total!$O:$AB, MATCH($AF3, 各隊total!$A:$A, 0), COLUMN(A2)), "")} -> .319 | AY3: {=IFERROR(INDEX(各隊total!$P:$AB, MATCH($AF3, 各隊total!$A:$A, 0), COLUMN(A2)), "")} -> .380 | AZ3: {=IFERROR(INDEX(各隊total!$Q:$AB, MATCH($AF3, 各隊total!$A:$A, 0), COLUMN(A2)), "")} -> .699 | BA3: {=IFERROR(INDEX(各隊total!$R:$AB, MATCH($AF3, 各隊total!$A:$A, 0), COLUMN(A2)), "")} -> 0 | BB3: {=IFERROR(INDEX(各隊total!$S:$AB, MATCH($AF3, 各隊total!$A:$A, 0), COLUMN(A2)), "")} -> 117.4 | BC3: {=IFERROR(INDEX(各隊total!$T:$AB, MATCH($AF3, 各隊total!$A:$A, 0), COLUMN(A2)), "")} -> 4.2 | BD3: {=IFERROR(INDEX(各隊total!$U:$AB, MATCH($AF3, 各隊total!$A:$A, 0), COLUMN(A2)), "")} -> .106 | BE3: {=IFERROR(INDEX(各隊total!$V:$AB, MATCH($AF3, 各隊total!$A:$A, 0), COLUMN(A2)), "")} -> 0.50 | BF3: {=IFERROR(INDEX(各隊total!$W:$AB, MATCH($AF3, 各隊total!$A:$A, 0), COLUMN(A2)), "")} -> .149 | BG3: {=IFERROR(INDEX(各隊total!$X:$AB, MATCH($AF3, 各隊total!$A:$A, 0), COLUMN(A2)), "")} -> .283 | BH3: {=IFERROR(INDEX(各隊total!$Y:$AB, MATCH($AF3, 各隊total!$A:$A, 0), COLUMN(A2)), "")} -> 4.17 | BI3: {=IFERROR(INDEX(各隊total!$Z:$AB, MATCH($AF3, 各隊total!$A:$A, 0), COLUMN(A2)), "")} -> 80 | BJ3: {=IFERROR(INDEX(各隊total!$AA:$AB, MATCH($AF3, 各隊total!$A:$A, 0), COLUMN(A2)), "")} -> 1076 | BK3: {=IFERROR(INDEX(各隊total!$AB:$AB, MATCH($AF3, 各隊total!$A:$A, 0), COLUMN(A2)), "")} -> 31.6 | BL3: {=IFERROR(INDEX(各隊total!$C:$AB, MATCH($AF3, 各隊total!$A:$A, 0), COLUMN(AA2)), "")} | BM3: 0.181 | BN3: 0.2 | BO3: 1 | BP3: 0.251 | BQ3: 0.27 | BR3: 1 | BS3: 0.311 | BT3: 0.34 | BU3: 1 | BV3: 3.1 | BW3: 3.4 | BX3: 1 | BY3: 2.9 | BZ3: 3.2 | CA3: 1 | CB3: =CF3+CJ3+CK3+CM3+CO3+CP3+CQ3+CR3 -> 4.8 | CC3: =CU3+CV3+CY3+CZ3+DA3 -> 4.25 | CF3: =VLOOKUP(ROUND(CF2/CD2, 2), $BV$2:$BX$12, 3, TRUE)*BX$1 -> 0.75 | CJ3: =VLOOKUP(ROUND(CJ2/CD2, 2), $BM$15:$BO$25, 3, TRUE)*BO$14 -> 0.3 | CK3: =VLOOKUP(ROUND(CK2/CD2, 2), $BY$2:$CA$12, 3, TRUE)*CA$1 -> 0.5 | CM3: =VLOOKUP(ROUND(CM2/CN2, 2), $BP$15:$BR$25, 3, TRUE)*BR$14 -> 0.6 | CO3: =VLOOKUP(ROUND(CO2/CD2, 2), $BS$15:$BU$25, 3, TRUE)*BU$14 -> 0.35 | CP3: =VLOOKUP(CP2*1, BM$2:BO$12, 3, TRUE)*BO$1 -> 0.5 | CQ3: =VLOOKUP(CQ2*1, BP$2:BR$12, 3, TRUE)*BR$1 -> 1.2 | CR3: =VLOOKUP(CR2*1, BS$2:BU$12, 3, TRUE)*BU$1 -> 0.6 | CU3: =VLOOKUP(CU2*1, BM$28:BO$38, 3, TRUE)*BO$27 -> 0.9 | CV3: =VLOOKUP(CV2*1, BP$28:BR$38, 3, TRUE)*BR$27 -> 1.75 | CY3: =VLOOKUP(CY2*1, BS$28:BU$38, 3, TRUE)*BU$27 -> 0.6 | CZ3: =VLOOKUP(CZ2*1, BV$28:BX$38, 3, TRUE)*BX$27 -> 0.6 | DA3: =VLOOKUP(DA2*1, BY$28:CA$38, 3, TRUE)*CA$27 -> 0.4 | DH3: =DJ3+DL3+DM3+DN3+DO3-DP3-DQ3+DR3 -> 2.8 | DI3: =DU3+DX3+EA3+ED3+EE3+EF3 -> 5 | DJ3: =VLOOKUP(DJ2*1, $FK$2:$FM$12, 3, TRUE)*$FM$1 -> 1.5 | DL3: =VLOOKUP(DL2*1, $FN$2:$FP$12, 3, TRUE)*$FP$1 -> 0.3 | DM3: =VLOOKUP(DM2*1, $FQ$2:$FS$12, 3, TRUE)*$FS$1 -> 0 | DN3: =VLOOKUP(DN2*1, $FT$2:$FV$12, 3, TRUE)*$FV$1 -> 1 | DO3: =VLOOKUP(DO2*1, $FW$2:$FY$12, 3, TRUE)*$FY$1 -> 0.5 | DP3: =VLOOKUP(DP2*1, $FK$14:$FM$25, 3, TRUE)*$FM$14 -> 1 | DQ3: =VLOOKUP(DQ2*1, $FN$14:$FP$25, 3, TRUE)*$FP$14 -> 1 | DR3: =VLOOKUP(DR2*1, $FQ$14:$FS$25, 3, TRUE)*$FS$14 -> 1.5 | DU3: =VLOOKUP(DU2*1, $FK$27:$FM$38, 3, TRUE)*$FM$27 -> 0 | DX3: =VLOOKUP(DX2*1, $FN$27:$FP$38, 3, TRUE)*$FP$27 -> 0 | EA3: =VLOOKUP(EA2*1, $FQ$27:$FS$38, 3, TRUE)*$FS$27 -> 0 | ED3: =VLOOKUP(ED2*1, $FT$27:$FV$38, 3, TRUE)*$FV$27 -> 0 | EE3: =VLOOKUP(EE2*1, $FW$27:$FY$38, 3, TRUE)*$FY$27 -> 1.5 | EF3: =VLOOKUP(EF2*1, $FK$40:$FM$51, 3, TRUE)*$FM$40 -> 3.5 | EK3: =EM3+EO3+EP3+EQ3+ER3-ES3-ET3+EU3 -> #VALUE! | EL3: =EX3+FA3+FD3+FG3+FH3+FI3 -> #VALUE! | EM3: =VLOOKUP(EM2*1, $FK$2:$FM$12, 3, TRUE)*$FM$1 -> #VALUE! | EO3: =VLOOKUP(EO2*1, $FN$2:$FP$12, 3, TRUE)*$FP$1 -> #VALUE! | EP3: =VLOOKUP(EP2*1, $FQ$2:$FS$12, 3, TRUE)*$FS$1 -> #VALUE! | EQ3: =VLOOKUP(EQ2*1, $FT$2:$FV$12, 3, TRUE)*$FV$1 -> #VALUE! | ER3: =VLOOKUP(ER2*1, $FW$2:$FY$12, 3, TRUE)*$FY$1 -> #VALUE! | ES3: =VLOOKUP(ES2*1, $FK$14:$FM$25, 3, TRUE)*$FM$14 -> #VALUE! | ET3: =VLOOKUP(ET2*1, $FN$14:$FP$25, 3, TRUE)*$FP$14 -> #VALUE! | EU3: =VLOOKUP(EU2*1, $FQ$14:$FS$25, 3, TRUE)*$FS$14 -> #VALUE! | EX3: =VLOOKUP(EX2*1, $FK$27:$FM$38, 3, TRUE)*$FM$27 -> #VALUE! | FA3: =VLOOKUP(FA2*1, $FN$27:$FP$38, 3, TRUE)*$FP$27 -> #VALUE! | FD3: =VLOOKUP(FD2*1, $FQ$27:$FS$38, 3, TRUE)*$FS$27 -> #VALUE! | FG3: =VLOOKUP(FG2*1, $FT$27:$FV$38, 3, TRUE)*$FV$27 -> #VALUE! | FH3: =VLOOKUP(FH2*1, $FW$27:$FY$38, 3, TRUE)*$FY$27 -> #VALUE! | FI3: =VLOOKUP(FI2*1, $FK$40:$FM$51, 3, TRUE)*$FM$40 -> #VALUE! | FK3: 3.1 | FL3: 5.5 | FM3: 1 | FN3: 1.6 | FO3: 2.5 | FP3: 1 | FQ3: 1.3 | FR3: 2.2 | FS3: 1 | FT3: 0.31 | FU3: 0.5 | FV3: 1 | FW3: 0.21 | FX3: 0.4 | FY3: 1
A4: 2 | B4: 20260428 | C4: 06:40 | D4: 0 | E4: 紅雀 | F4: 0 | G4: 0.29 | H4: 0 | I4: 海盜 | J4: 1分贏 | K4: 0.71 | L4: {=IFERROR(SUBSTITUTE(INDEX(正負盤!$6:$20, ROW(A1), MATCH(1, (MONTH(正負盤!$4:$4)=MONTH(DATE(LEFT($A$1,4),MID($A$1,5,2),RIGHT($A$1,2))-10))*(DAY(正負盤!$4:$4)=DAY(DATE(LEFT($A$1,4),MID($A$1,5,2),RIGHT($A$1,2))-10)), 0)), 0, "-"), "")} -> O | M4: {=IFERROR(SUBSTITUTE(INDEX(正負盤!$6:$20, ROW(A1), MATCH(1, (MONTH(正負盤!$4:$4)=MONTH(DATE(LEFT($A$1,4),MID($A$1,5,2),RIGHT($A$1,2))-9))*(DAY(正負盤!$4:$4)=DAY(DATE(LEFT($A$1,4),MID($A$1,5,2),RIGHT($A$1,2))-9)), 0)), 0, "-"), "")} -> O | N4: {=IFERROR(SUBSTITUTE(INDEX(正負盤!$6:$20, ROW(A1), MATCH(1, (MONTH(正負盤!$4:$4)=MONTH(DATE(LEFT($A$1,4),MID($A$1,5,2),RIGHT($A$1,2))-8))*(DAY(正負盤!$4:$4)=DAY(DATE(LEFT($A$1,4),MID($A$1,5,2),RIGHT($A$1,2))-8)), 0)), 0, "-"), "")} -> X | O4: {=IFERROR(SUBSTITUTE(INDEX(正負盤!$6:$20, ROW(A1), MATCH(1, (MONTH(正負盤!$4:$4)=MONTH(DATE(LEFT($A$1,4),MID($A$1,5,2),RIGHT($A$1,2))-7))*(DAY(正負盤!$4:$4)=DAY(DATE(LEFT($A$1,4),MID($A$1,5,2),RIGHT($A$1,2))-7)), 0)), 0, "-"), "")} -> X | P4: {=IFERROR(SUBSTITUTE(INDEX(正負盤!$6:$20, ROW(A1), MATCH(1, (MONTH(正負盤!$4:$4)=MONTH(DATE(LEFT($A$1,4),MID($A$1,5,2),RIGHT($A$1,2))-6))*(DAY(正負盤!$4:$4)=DAY(DATE(LEFT($A$1,4),MID($A$1,5,2),RIGHT($A$1,2))-6)), 0)), 0, "-"), "")} -> O | Q4: {=IFERROR(SUBSTITUTE(INDEX(正負盤!$6:$20, ROW(A1), MATCH(1, (MONTH(正負盤!$4:$4)=MONTH(DATE(LEFT($A$1,4),MID($A$1,5,2),RIGHT($A$1,2))-5))*(DAY(正負盤!$4:$4)=DAY(DATE(LEFT($A$1,4),MID($A$1,5,2),RIGHT($A$1,2))-5)), 0)), 0, "-"), "")} | R4: {=IFERROR(SUBSTITUTE(INDEX(正負盤!$6:$20, ROW(A1), MATCH(1, (MONTH(正負盤!$4:$4)=MONTH(DATE(LEFT($A$1,4),MID($A$1,5,2),RIGHT($A$1,2))-4))*(DAY(正負盤!$4:$4)=DAY(DATE(LEFT($A$1,4),MID($A$1,5,2),RIGHT($A$1,2))-4)), 0)), 0, "-"), "")} -> O | S4: {=IFERROR(SUBSTITUTE(INDEX(正負盤!$6:$20, ROW(A1), MATCH(1, (MONTH(正負盤!$4:$4)=MONTH(DATE(LEFT($A$1,4),MID($A$1,5,2),RIGHT($A$1,2))-3))*(DAY(正負盤!$4:$4)=DAY(DATE(LEFT($A$1,4),MID($A$1,5,2),RIGHT($A$1,2))-3)), 0)), 0, "-"), "")} -> X | T4: {=IFERROR(SUBSTITUTE(INDEX(正負盤!$6:$20, ROW(A1), MATCH(1, (MONTH(正負盤!$4:$4)=MONTH(DATE(LEFT($A$1,4),MID($A$1,5,2),RIGHT($A$1,2))-2))*(DAY(正負盤!$4:$4)=DAY(DATE(LEFT($A$1,4),MID($A$1,5,2),RIGHT($A$1,2))-2)), 0)), 0, "-"), "")} -> X | U4: {=IFERROR(SUBSTITUTE(INDEX(正負盤!$6:$20, ROW(A1), MATCH(1, (MONTH(正負盤!$4:$4)=MONTH(DATE(LEFT($A$1,4),MID($A$1,5,2),RIGHT($A$1,2))-1))*(DAY(正負盤!$4:$4)=DAY(DATE(LEFT($A$1,4),MID($A$1,5,2),RIGHT($A$1,2))-1)), 0)), 0, "-"), "")} -> X | V4: =C4 -> 06:40 | W4: =E4 -> 紅雀 | X4: {=_xlfn.LET(_xlpm.s,SUBSTITUTE(Y4,".",""),_xlpm.c,RIGHT(_xlpm.s,1),_xlpm.n,ROW(INDIRECT("1:"&LEN(_xlpm.s))),_xlpm.cnt,MAX(IF(RIGHT(_xlpm.s,_xlpm.n)=REPT(_xlpm.c,_xlpm.n),_xlpm.n,0)),IF(_xlpm.cnt>=2,_xlpm.cnt&"連"&_xlpm.c,"1"&_xlpm.c))} -> 3連X | Y4: {=INDEX(各隊正負!$F:$F, MATCH("*"&$W4&"*", 各隊正負!$A:$A, 0)+6)} -> O.O.O.O.O.X.O.X.X.X | AB4: {=INDEX(各隊正負!$F:$F, MATCH("*"&$W4&"*", 各隊正負!$A:$A, 0)+4)} -> W.W.W.W.W.L.W.L.L.L | AE4: {=_xlfn.LET(_xlpm.s,SUBSTITUTE(AB4,".",""),_xlpm.c,RIGHT(_xlpm.s,1),_xlpm.n,ROW(INDIRECT("1:"&LEN(_xlpm.s))),_xlpm.cnt,MAX(IF(RIGHT(_xlpm.s,_xlpm.n)=REPT(_xlpm.c,_xlpm.n),_xlpm.n,0)),_xlpm.suffix,IF(_xlpm.c="W","勝","敗"),IF(_xlpm.cnt>=2,_xlpm.cnt&"連"&_xlpm.suffix,"1"&_xlpm.suffix))} -> 3連敗 | AF4: =E4 -> 紅雀 | AG4: {=IFERROR(INDEX(各隊total!$B:$AB, MATCH($AF4, 各隊total!$A:$A, 0), COLUMN(A3)), "")} -> 27 | AH4: =CB7 -> 4.5 | AI4: =VLOOKUP(AH4*1, BV$15:BX$25, 3, TRUE) -> B | AJ4: =CC7 -> 4.35 | AK4: =VLOOKUP(AJ4*1, BY$15:CA$25, 3, TRUE) -> B | AL4: {=IFERROR(INDEX(各隊total!$C:$AB, MATCH($AF4, 各隊total!$A:$A, 0), COLUMN(A3)), "")} -> 901 | AM4: {=IFERROR(INDEX(各隊total!$D:$AB, MATCH($AF4, 各隊total!$A:$A, 0), COLUMN(A3)), "")} -> 125 | AN4: {=IFERROR(INDEX(各隊total!$E:$AB, MATCH($AF4, 各隊total!$A:$A, 0), COLUMN(A3)), "")} -> 212 | AO4: {=IFERROR(INDEX(各隊total!$F:$AB, MATCH($AF4, 各隊total!$A:$A, 0), COLUMN(A3)), "")} -> 35 | AP4: {=IFERROR(INDEX(各隊total!$G:$AB, MATCH($AF4, 各隊total!$A:$A, 0), COLUMN(A3)), "")} -> 1 | AQ4: {=IFERROR(INDEX(各隊total!$H:$AB, MATCH($AF4, 各隊total!$A:$A, 0), COLUMN(A3)), "")} -> 34 | AR4: {=IFERROR(INDEX(各隊total!$I:$AB, MATCH($AF4, 各隊total!$A:$A, 0), COLUMN(A3)), "")} -> 122 | AS4: {=IFERROR(INDEX(各隊total!$J:$AB, MATCH($AF4, 各隊total!$A:$A, 0), COLUMN(A3)), "")} -> 351 | AT4: {=IFERROR(INDEX(各隊total!$K:$AB, MATCH($AF4, 各隊total!$A:$A, 0), COLUMN(A3)), "")} -> 101 | AU4: {=IFERROR(INDEX(各隊total!$L:$AB, MATCH($AF4, 各隊total!$A:$A, 0), COLUMN(A3)), "")} -> 225 | AV4: {=IFERROR(INDEX(各隊total!$M:$AB, MATCH($AF4, 各隊total!$A:$A, 0), COLUMN(A3)), "")} -> 20 | AW4: {=IFERROR(INDEX(各隊total!$N:$AB, MATCH($AF4, 各隊total!$A:$A, 0), COLUMN(A3)), "")} -> .235 | AX4: {=IFERROR(INDEX(各隊total!$O:$AB, MATCH($AF4, 各隊total!$A:$A, 0), COLUMN(A3)), "")} -> .324 | AY4: {=IFERROR(INDEX(各隊total!$P:$AB, MATCH($AF4, 各隊total!$A:$A, 0), COLUMN(A3)), "")} -> .390 | AZ4: {=IFERROR(INDEX(各隊total!$Q:$AB, MATCH($AF4, 各隊total!$A:$A, 0), COLUMN(A3)), "")} -> .713 | BA4: {=IFERROR(INDEX(各隊total!$R:$AB, MATCH($AF4, 各隊total!$A:$A, 0), COLUMN(A3)), "")} -> 0 | BB4: {=IFERROR(INDEX(各隊total!$S:$AB, MATCH($AF4, 各隊total!$A:$A, 0), COLUMN(A3)), "")} -> 118.2 | BC4: {=IFERROR(INDEX(各隊total!$T:$AB, MATCH($AF4, 各隊total!$A:$A, 0), COLUMN(A3)), "")} -> 4.3 | BD4: {=IFERROR(INDEX(各隊total!$U:$AB, MATCH($AF4, 各隊total!$A:$A, 0), COLUMN(A3)), "")} -> .097 | BE4: {=IFERROR(INDEX(各隊total!$V:$AB, MATCH($AF4, 各隊total!$A:$A, 0), COLUMN(A3)), "")} -> 0.45 | BF4: {=IFERROR(INDEX(各隊total!$W:$AB, MATCH($AF4, 各隊total!$A:$A, 0), COLUMN(A3)), "")} -> .154 | BG4: {=IFERROR(INDEX(各隊total!$X:$AB, MATCH($AF4, 各隊total!$A:$A, 0), COLUMN(A3)), "")} -> .283 | BH4: {=IFERROR(INDEX(各隊total!$Y:$AB, MATCH($AF4, 各隊total!$A:$A, 0), COLUMN(A3)), "")} -> 3.84 | BI4: {=IFERROR(INDEX(各隊total!$Z:$AB, MATCH($AF4, 各隊total!$A:$A, 0), COLUMN(A3)), "")} -> 70 | BJ4: {=IFERROR(INDEX(各隊total!$AA:$AB, MATCH($AF4, 各隊total!$A:$A, 0), COLUMN(A3)), "")} -> 1045 | BK4: {=IFERROR(INDEX(各隊total!$AB:$AB, MATCH($AF4, 各隊total!$A:$A, 0), COLUMN(A3)), "")} -> 26.5 | BL4: {=IFERROR(INDEX(各隊total!$C:$AB, MATCH($AF4, 各隊total!$A:$A, 0), COLUMN(AA3)), "")} | BM4: 0.201 | BN4: 0.215 | BO4: 2 | BP4: 0.271 | BQ4: 0.285 | BR4: 2 | BS4: 0.341 | BT4: 0.37 | BU4: 2 | BV4: 3.5 | BW4: 3.8 | BX4: 2 | BY4: 3.3 | BZ4: 3.6 | CA4: 2 | CB4: =AF3 -> 守護者 | CD4: =AG3 -> 29 | CE4: =AL3 -> 947 | CF4: =AM3 -> 118 | CG4: =AN3 -> 219 | CH4: =AO3 -> 49 | CI4: =AP3 -> 1 | CJ4: =AQ3 -> 30 | CK4: =AR3 -> 113 | CL4: =AS3 -> 360 | ... DD4: =BK3 -> 31.6 | DF4: =先發名單!H$2 -> J. Aranda | DG4: {=IFERROR(INDEX(球員狀態!$C$2:$C$5000, MATCH(1, (球員狀態!$A$2:$A$5000=$DF$1)*(ISNUMBER(SEARCH($DF4, 球員狀態!$B$2:$B$5000))), 0)), "")} | DJ4: {=IFERROR(INDEX(球員狀態!$F$2:$F$5000, MATCH(1, (球員狀態!$A$2:$A$5000=$DF$1)*(ISNUMBER(SEARCH($DF4, 球員狀態!$B$2:$B$5000))), 0)), "")} | DK4: {=IFERROR(INDEX(球員狀態!$G$2:$G$5000, MATCH(1, (球員狀態!$A$2:$A$5000=$DF$1)*(ISNUMBER(SEARCH($DF4, 球員狀態!$B$2:$B$5000))), 0)), "")} | DL4: {=IFERROR(INDEX(球員狀態!H$2:H$5000, MATCH(1, (球員狀態!$A$2:$A$5000=$DF$1)*(ISNUMBER(SEARCH($DF4, 球員狀態!$B$2:$B$5000))), 0)), "")} | DM4: {=IFERROR(INDEX(球員狀態!I$2:I$5000, MATCH(1, (球員狀態!$A$2:$A$5000=$DF$1)*(ISNUMBER(SEARCH($DF4, 球員狀態!$B$2:$B$5000))), 0)), "")} | DN4: {=IFERROR(INDEX(球員狀態!J$2:J$5000, MATCH(1, (球員狀態!$A$2:$A$5000=$DF$1)*(ISNUMBER(SEARCH($DF4, 球員狀態!$B$2:$B$5000))), 0)), "")} | DO4: {=IFERROR(INDEX(球員狀態!K$2:K$5000, MATCH(1, (球員狀態!$A$2:$A$5000=$DF$1)*(ISNUMBER(SEARCH($DF4, 球員狀態!$B$2:$B$5000))), 0)), "")} | DP4: {=IFERROR(INDEX(球員狀態!L$2:L$5000, MATCH(1, (球員狀態!$A$2:$A$5000=$DF$1)*(ISNUMBER(SEARCH($DF4, 球員狀態!$B$2:$B$5000))), 0)), "")} | DQ4: {=IFERROR(INDEX(球員狀態!M$2:M$5000, MATCH(1, (球員狀態!$A$2:$A$5000=$DF$1)*(ISNUMBER(SEARCH($DF4, 球員狀態!$B$2:$B$5000))), 0)), "")} | DR4: {=IFERROR(INDEX(球員狀態!N$2:N$5000, MATCH(1, (球員狀態!$A$2:$A$5000=$DF$1)*(ISNUMBER(SEARCH($DF4, 球員狀態!$B$2:$B$5000))), 0)), "")} | DS4: {=IFERROR(INDEX(球員狀態!O$2:O$5000, MATCH(1, (球員狀態!$A$2:$A$5000=$DF$1)*(ISNUMBER(SEARCH($DF4, 球員狀態!$B$2:$B$5000))), 0)), "")} | ... EF4: {=IFERROR(INDEX(球員狀態!AB$2:AB$5000, MATCH(1, (球員狀態!$A$2:$A$5000=$DF$1)*(ISNUMBER(SEARCH($DF4, 球員狀態!$B$2:$B$5000))), 0)), "")} | EI4: =先發名單!P$2 -> Steven Kwan | EJ4: {=IFERROR(INDEX(球員狀態!$C$2:$C$5000, MATCH(1, (球員狀態!$A$2:$A$5000=$EI$1)*(ISNUMBER(SEARCH($EI4, 球員狀態!$B$2:$B$5000))), 0)), "")} -> LF | EM4: {=IFERROR(INDEX(球員狀態!F$2:F$5000, MATCH(1, (球員狀態!$A$2:$A$5000=$EI$1)*(ISNUMBER(SEARCH($EI4, 球員狀態!$B$2:$B$5000))), 0)), "")} -> 10 | EN4: {=IFERROR(INDEX(球員狀態!G$2:G$5000, MATCH(1, (球員狀態!$A$2:$A$5000=$EI$1)*(ISNUMBER(SEARCH($EI4, 球員狀態!$B$2:$B$5000))), 0)), "")} -> 23 | EO4: {=IFERROR(INDEX(球員狀態!H$2:H$5000, MATCH(1, (球員狀態!$A$2:$A$5000=$EI$1)*(ISNUMBER(SEARCH($EI4, 球員狀態!$B$2:$B$5000))), 0)), "")} -> 3 | EP4: {=IFERROR(INDEX(球員狀態!I$2:I$5000, MATCH(1, (球員狀態!$A$2:$A$5000=$EI$1)*(ISNUMBER(SEARCH($EI4, 球員狀態!$B$2:$B$5000))), 0)), "")} -> 0 | EQ4: {=IFERROR(INDEX(球員狀態!J$2:J$5000, MATCH(1, (球員狀態!$A$2:$A$5000=$EI$1)*(ISNUMBER(SEARCH($EI4, 球員狀態!$B$2:$B$5000))), 0)), "")} -> 1 | ER4: {=IFERROR(INDEX(球員狀態!K$2:K$5000, MATCH(1, (球員狀態!$A$2:$A$5000=$EI$1)*(ISNUMBER(SEARCH($EI4, 球員狀態!$B$2:$B$5000))), 0)), "")} -> 8 | ES4: {=IFERROR(INDEX(球員狀態!L$2:L$5000, MATCH(1, (球員狀態!$A$2:$A$5000=$EI$1)*(ISNUMBER(SEARCH($EI4, 球員狀態!$B$2:$B$5000))), 0)), "")} -> 29 | ET4: {=IFERROR(INDEX(球員狀態!M$2:M$5000, MATCH(1, (球員狀態!$A$2:$A$5000=$EI$1)*(ISNUMBER(SEARCH($EI4, 球員狀態!$B$2:$B$5000))), 0)), "")} -> 12 | ... FI4: {=IFERROR(INDEX(球員狀態!AB$2:AB$5000, MATCH(1, (球員狀態!$A$2:$A$5000=$EI$1)*(ISNUMBER(SEARCH($EI4, 球員狀態!$B$2:$B$5000))), 0)), "")} -> 4 | FK4: 5.6 | FL4: 8 | FM4: 2 | FN4: 2.6 | FO4: 3.5 | FP4: 2 | FQ4: 2.3 | FR4: 3.2 | FS4: 2 | FT4: 0.51 | FU4: 0.7 | FV4: 2 | FW4: 0.41 | FX4: 0.6 | FY4: 2
A5: 3 | B5: 20260428 | C5: 07:07 | D5: 0 | E5: 紅襪 | F5: 0 | G5: 0.26 | H5: 0 | I5: 藍鳥 | J5: 1分贏 | K5: 0.74 | L5: {=IFERROR(SUBSTITUTE(INDEX(正負盤!$6:$20, ROW(A2), MATCH(1, (MONTH(正負盤!$4:$4)=MONTH(DATE(LEFT($A$1,4),MID($A$1,5,2),RIGHT($A$1,2))-10))*(DAY(正負盤!$4:$4)=DAY(DATE(LEFT($A$1,4),MID($A$1,5,2),RIGHT($A$1,2))-10)), 0)), 0, "-"), "")} -> X | M5: {=IFERROR(SUBSTITUTE(INDEX(正負盤!$6:$20, ROW(A2), MATCH(1, (MONTH(正負盤!$4:$4)=MONTH(DATE(LEFT($A$1,4),MID($A$1,5,2),RIGHT($A$1,2))-9))*(DAY(正負盤!$4:$4)=DAY(DATE(LEFT($A$1,4),MID($A$1,5,2),RIGHT($A$1,2))-9)), 0)), 0, "-"), "")} -> X | N5: {=IFERROR(SUBSTITUTE(INDEX(正負盤!$6:$20, ROW(A2), MATCH(1, (MONTH(正負盤!$4:$4)=MONTH(DATE(LEFT($A$1,4),MID($A$1,5,2),RIGHT($A$1,2))-8))*(DAY(正負盤!$4:$4)=DAY(DATE(LEFT($A$1,4),MID($A$1,5,2),RIGHT($A$1,2))-8)), 0)), 0, "-"), "")} -> O | O5: {=IFERROR(SUBSTITUTE(INDEX(正負盤!$6:$20, ROW(A2), MATCH(1, (MONTH(正負盤!$4:$4)=MONTH(DATE(LEFT($A$1,4),MID($A$1,5,2),RIGHT($A$1,2))-7))*(DAY(正負盤!$4:$4)=DAY(DATE(LEFT($A$1,4),MID($A$1,5,2),RIGHT($A$1,2))-7)), 0)), 0, "-"), "")} -> X | P5: {=IFERROR(SUBSTITUTE(INDEX(正負盤!$6:$20, ROW(A2), MATCH(1, (MONTH(正負盤!$4:$4)=MONTH(DATE(LEFT($A$1,4),MID($A$1,5,2),RIGHT($A$1,2))-6))*(DAY(正負盤!$4:$4)=DAY(DATE(LEFT($A$1,4),MID($A$1,5,2),RIGHT($A$1,2))-6)), 0)), 0, "-"), "")} -> X | Q5: {=IFERROR(SUBSTITUTE(INDEX(正負盤!$6:$20, ROW(A2), MATCH(1, (MONTH(正負盤!$4:$4)=MONTH(DATE(LEFT($A$1,4),MID($A$1,5,2),RIGHT($A$1,2))-5))*(DAY(正負盤!$4:$4)=DAY(DATE(LEFT($A$1,4),MID($A$1,5,2),RIGHT($A$1,2))-5)), 0)), 0, "-"), "")} | R5: {=IFERROR(SUBSTITUTE(INDEX(正負盤!$6:$20, ROW(A2), MATCH(1, (MONTH(正負盤!$4:$4)=MONTH(DATE(LEFT($A$1,4),MID($A$1,5,2),RIGHT($A$1,2))-4))*(DAY(正負盤!$4:$4)=DAY(DATE(LEFT($A$1,4),MID($A$1,5,2),RIGHT($A$1,2))-4)), 0)), 0, "-"), "")} -> X | S5: {=IFERROR(SUBSTITUTE(INDEX(正負盤!$6:$20, ROW(A2), MATCH(1, (MONTH(正負盤!$4:$4)=MONTH(DATE(LEFT($A$1,4),MID($A$1,5,2),RIGHT($A$1,2))-3))*(DAY(正負盤!$4:$4)=DAY(DATE(LEFT($A$1,4),MID($A$1,5,2),RIGHT($A$1,2))-3)), 0)), 0, "-"), "")} -> O | T5: {=IFERROR(SUBSTITUTE(INDEX(正負盤!$6:$20, ROW(A2), MATCH(1, (MONTH(正負盤!$4:$4)=MONTH(DATE(LEFT($A$1,4),MID($A$1,5,2),RIGHT($A$1,2))-2))*(DAY(正負盤!$4:$4)=DAY(DATE(LEFT($A$1,4),MID($A$1,5,2),RIGHT($A$1,2))-2)), 0)), 0, "-"), "")} -> O | U5: {=IFERROR(SUBSTITUTE(INDEX(正負盤!$6:$20, ROW(A2), MATCH(1, (MONTH(正負盤!$4:$4)=MONTH(DATE(LEFT($A$1,4),MID($A$1,5,2),RIGHT($A$1,2))-1))*(DAY(正負盤!$4:$4)=DAY(DATE(LEFT($A$1,4),MID($A$1,5,2),RIGHT($A$1,2))-1)), 0)), 0, "-"), "")} -> O | W5: =I4 -> 海盜 | X5: {=_xlfn.LET(_xlpm.s,SUBSTITUTE(Y5,".",""),_xlpm.c,RIGHT(_xlpm.s,1),_xlpm.n,ROW(INDIRECT("1:"&LEN(_xlpm.s))),_xlpm.cnt,MAX(IF(RIGHT(_xlpm.s,_xlpm.n)=REPT(_xlpm.c,_xlpm.n),_xlpm.n,0)),IF(_xlpm.cnt>=2,_xlpm.cnt&"連"&_xlpm.c,"1"&_xlpm.c))} -> 1X | Y5: {=INDEX(各隊正負!$F:$F, MATCH("*"&$W5&"*", 各隊正負!$A:$A, 0)+6)} -> O.X.O.X.O.X.X.O.O.X | AB5: {=INDEX(各隊正負!$F:$F, MATCH("*"&$W5&"*", 各隊正負!$A:$A, 0)+4)} -> W.L.W.L.W.L.L.W.W.L | AE5: {=_xlfn.LET(_xlpm.s,SUBSTITUTE(AB5,".",""),_xlpm.c,RIGHT(_xlpm.s,1),_xlpm.n,ROW(INDIRECT("1:"&LEN(_xlpm.s))),_xlpm.cnt,MAX(IF(RIGHT(_xlpm.s,_xlpm.n)=REPT(_xlpm.c,_xlpm.n),_xlpm.n,0)),_xlpm.suffix,IF(_xlpm.c="W","勝","敗"),IF(_xlpm.cnt>=2,_xlpm.cnt&"連"&_xlpm.suffix,"1"&_xlpm.suffix))} -> 1敗 | AF5: =I4 -> 海盜 | AG5: {=IFERROR(INDEX(各隊total!$B:$AB, MATCH($AF5, 各隊total!$A:$A, 0), COLUMN(A4)), "")} -> 28 | AH5: =CB9 -> 4.4 | AI5: =VLOOKUP(AH5*1, BV$15:BX$25, 3, TRUE) -> B | AJ5: =CC9 -> 4.7 | AK5: =VLOOKUP(AJ5*1, BY$15:CA$25, 3, TRUE) -> B+ | AL5: {=IFERROR(INDEX(各隊total!$C:$AB, MATCH($AF5, 各隊total!$A:$A, 0), COLUMN(A4)), "")} -> 971 | AM5: {=IFERROR(INDEX(各隊total!$D:$AB, MATCH($AF5, 各隊total!$A:$A, 0), COLUMN(A4)), "")} -> 135 | AN5: {=IFERROR(INDEX(各隊total!$E:$AB, MATCH($AF5, 各隊total!$A:$A, 0), COLUMN(A4)), "")} -> 234 | AO5: {=IFERROR(INDEX(各隊total!$F:$AB, MATCH($AF5, 各隊total!$A:$A, 0), COLUMN(A4)), "")} -> 36 | AP5: {=IFERROR(INDEX(各隊total!$G:$AB, MATCH($AF5, 各隊total!$A:$A, 0), COLUMN(A4)), "")} -> 2 | AQ5: {=IFERROR(INDEX(各隊total!$H:$AB, MATCH($AF5, 各隊total!$A:$A, 0), COLUMN(A4)), "")} -> 29 | AR5: {=IFERROR(INDEX(各隊total!$I:$AB, MATCH($AF5, 各隊total!$A:$A, 0), COLUMN(A4)), "")} -> 130 | AS5: {=IFERROR(INDEX(各隊total!$J:$AB, MATCH($AF5, 各隊total!$A:$A, 0), COLUMN(A4)), "")} -> 361 | AT5: {=IFERROR(INDEX(各隊total!$K:$AB, MATCH($AF5, 各隊total!$A:$A, 0), COLUMN(A4)), "")} -> 108 | AU5: {=IFERROR(INDEX(各隊total!$L:$AB, MATCH($AF5, 各隊total!$A:$A, 0), COLUMN(A4)), "")} -> 271 | AV5: {=IFERROR(INDEX(各隊total!$M:$AB, MATCH($AF5, 各隊total!$A:$A, 0), COLUMN(A4)), "")} -> 26 | AW5: {=IFERROR(INDEX(各隊total!$N:$AB, MATCH($AF5, 各隊total!$A:$A, 0), COLUMN(A4)), "")} -> .241 | AX5: {=IFERROR(INDEX(各隊total!$O:$AB, MATCH($AF5, 各隊total!$A:$A, 0), COLUMN(A4)), "")} -> .325 | AY5: {=IFERROR(INDEX(各隊total!$P:$AB, MATCH($AF5, 各隊total!$A:$A, 0), COLUMN(A4)), "")} -> .372 | AZ5: {=IFERROR(INDEX(各隊total!$Q:$AB, MATCH($AF5, 各隊total!$A:$A, 0), COLUMN(A4)), "")} -> .697 | BA5: {=IFERROR(INDEX(各隊total!$R:$AB, MATCH($AF5, 各隊total!$A:$A, 0), COLUMN(A4)), "")} -> 0 | BB5: {=IFERROR(INDEX(各隊total!$S:$AB, MATCH($AF5, 各隊total!$A:$A, 0), COLUMN(A4)), "")} -> 121.5 | BC5: {=IFERROR(INDEX(各隊total!$T:$AB, MATCH($AF5, 各隊total!$A:$A, 0), COLUMN(A4)), "")} -> 4.2 | BD5: {=IFERROR(INDEX(各隊total!$U:$AB, MATCH($AF5, 各隊total!$A:$A, 0), COLUMN(A4)), "")} -> .098 | BE5: {=IFERROR(INDEX(各隊total!$V:$AB, MATCH($AF5, 各隊total!$A:$A, 0), COLUMN(A4)), "")} -> 0.40 | BF5: {=IFERROR(INDEX(各隊total!$W:$AB, MATCH($AF5, 各隊total!$A:$A, 0), COLUMN(A4)), "")} -> .131 | BG5: {=IFERROR(INDEX(各隊total!$X:$AB, MATCH($AF5, 各隊total!$A:$A, 0), COLUMN(A4)), "")} -> .266 | BH5: {=IFERROR(INDEX(各隊total!$Y:$AB, MATCH($AF5, 各隊total!$A:$A, 0), COLUMN(A4)), "")} -> 3.96 | BI5: {=IFERROR(INDEX(各隊total!$Z:$AB, MATCH($AF5, 各隊total!$A:$A, 0), COLUMN(A4)), "")} -> 67 | BJ5: {=IFERROR(INDEX(各隊total!$AA:$AB, MATCH($AF5, 各隊total!$A:$A, 0), COLUMN(A4)), "")} -> 1106 | BK5: {=IFERROR(INDEX(各隊total!$AB:$AB, MATCH($AF5, 各隊total!$A:$A, 0), COLUMN(A4)), "")} -> 33.5 | BL5: {=IFERROR(INDEX(各隊total!$C:$AB, MATCH($AF5, 各隊total!$A:$A, 0), COLUMN(AA4)), "")} | BM5: 0.216 | BN5: 0.23 | BO5: 3 | BP5: 0.286 | BQ5: 0.3 | BR5: 3 | BS5: 0.371 | BT5: 0.395 | BU5: 3 | BV5: 3.9 | BW5: 4.2 | BX5: 3 | BY5: 3.7 | BZ5: 4 | CA5: 3 | CB5: =CF5+CJ5+CK5+CM5+CO5+CP5+CQ5+CR5 -> 4 | CC5: =CU5+CV5+CY5+CZ5+DA5 -> 5.55 | CF5: =VLOOKUP(ROUND(CF4/CD4, 2), $BV$2:$BX$12, 3, TRUE)*BX$1 -> 0.45 | CJ5: =VLOOKUP(ROUND(CJ4/CD4, 2), $BM$15:$BO$25, 3, TRUE)*BO$14 -> 0.4 | CK5: =VLOOKUP(ROUND(CK4/CD4, 2), $BY$2:$CA$12, 3, TRUE)*CA$1 -> 0.3 | CM5: =VLOOKUP(ROUND(CM4/CN4, 2), $BP$15:$BR$25, 3, TRUE)*BR$14 -> 0.6 | CO5: =VLOOKUP(ROUND(CO4/CD4, 2), $BS$15:$BU$25, 3, TRUE)*BU$14 -> 0.25 | CP5: =VLOOKUP(CP4*1, BM$2:BO$12, 3, TRUE)*BO$1 -> 0.4 | CQ5: =VLOOKUP(CQ4*1, BP$2:BR$12, 3, TRUE)*BR$1 -> 1 | CR5: =VLOOKUP(CR4*1, BS$2:BU$12, 3, TRUE)*BU$1 -> 0.6 | CU5: =VLOOKUP(CU4*1, BM$28:BO$38, 3, TRUE)*BO$27 -> 0.8 | CV5: =VLOOKUP(CV4*1, BP$28:BR$38, 3, TRUE)*BR$27 -> 1.4 | CY5: =VLOOKUP(CY4*1, BS$28:BU$38, 3, TRUE)*BU$27 -> 0.8 | CZ5: =VLOOKUP(CZ4*1, BV$28:BX$38, 3, TRUE)*BX$27 -> 0.75 | DA5: =VLOOKUP(DA4*1, BY$28:CA$38, 3, TRUE)*CA$27 -> 1.8 | DH5: =DJ5+DL5+DM5+DN5+DO5-DP5-DQ5+DR5 -> #VALUE! | DI5: =DU5+DX5+EA5+ED5+EE5+EF5 -> #VALUE! | DJ5: =VLOOKUP(DJ4*1, FK$2:FM$12, 3, TRUE)*FM$1 -> #VALUE! | DL5: =VLOOKUP(DL4*1, FN$2:FP$12, 3, TRUE)*FP$1 -> #VALUE! | DM5: =VLOOKUP(DM4*1, FQ$2:FS$12, 3, TRUE)*FS$1 -> #VALUE! | DN5: =VLOOKUP(DN4*1, FT$2:FV$12, 3, TRUE)*FV$1 -> #VALUE! | DO5: =VLOOKUP(DO4*1, FW$2:FY$12, 3, TRUE)*FY$1 -> #VALUE! | DP5: =VLOOKUP(DP4*1, FK$14:FM$25, 3, TRUE)*FM$14 -> #VALUE! | DQ5: =VLOOKUP(DQ4*1, FN$14:FP$25, 3, TRUE)*FP$14 -> #VALUE! | DR5: =VLOOKUP(DR4*1, FQ$14:FS$25, 3, TRUE)*FS$14 -> #VALUE! | DU5: =VLOOKUP(DU4*1, FK$27:FM$38, 3, TRUE)*FM$27 -> #VALUE! | DX5: =VLOOKUP(DX4*1, FN$27:FP$38, 3, TRUE)*FP$27 -> #VALUE! | EA5: =VLOOKUP(EA4*1, FQ$27:FS$38, 3, TRUE)*FS$27 -> #VALUE! | ED5: =VLOOKUP(ED4*1, FT$27:FV$38, 3, TRUE)*FV$27 -> #VALUE! | EE5: =VLOOKUP(EE4*1, FW$27:FY$38, 3, TRUE)*FY$27 -> #VALUE! | EF5: =VLOOKUP(EF4*1, FK$40:FM$51, 3, TRUE)*FM$40 -> #VALUE! | EK5: =EM5+EO5+EP5+EQ5+ER5-ES5-ET5+EU5 -> 1.45 | EL5: =EX5+FA5+FD5+FG5+FH5+FI5 -> #N/A | EM5: =VLOOKUP(EM4*1, $FK$2:$FM$12, 3, TRUE)*$FM$1 -> 0.75 | EO5: =VLOOKUP(EO4*1, $FN$2:$FP$12, 3, TRUE)*$FP$1 -> 0.3 | EP5: =VLOOKUP(EP4*1, $FQ$2:$FS$12, 3, TRUE)*$FS$1 -> 0 | EQ5: =VLOOKUP(EQ4*1, $FT$2:$FV$12, 3, TRUE)*$FV$1 -> 0.4 | ER5: =VLOOKUP(ER4*1, $FW$2:$FY$12, 3, TRUE)*$FY$1 -> 0.5 | ES5: =VLOOKUP(ES4*1, $FK$14:$FM$25, 3, TRUE)*$FM$14 -> 1 | ET5: =VLOOKUP(ET4*1, $FN$14:$FP$25, 3, TRUE)*$FP$14 -> 1 | EU5: =VLOOKUP(EU4*1, $FQ$14:$FS$25, 3, TRUE)*$FS$14 -> 1.5 | EX5: =VLOOKUP(EX4*1, $FK$27:$FM$38, 3, TRUE)*$FM$27 -> 0 | FA5: =VLOOKUP(FA4*1, $FN$27:$FP$38, 3, TRUE)*$FP$27 -> #N/A | FD5: =VLOOKUP(FD4*1, $FQ$27:$FS$38, 3, TRUE)*$FS$27 -> 0 | FG5: =VLOOKUP(FG4*1, $FT$27:$FV$38, 3, TRUE)*$FV$27 -> 0 | FH5: =VLOOKUP(FH4*1, $FW$27:$FY$38, 3, TRUE)*$FY$27 -> 1.5 | FI5: =VLOOKUP(FI4*1, $FK$40:$FM$51, 3, TRUE)*$FM$40 -> 3.5 | FK5: 8.1 | FL5: 10 | FM5: 3 | FN5: 3.6 | FO5: 4.5 | FP5: 3 | FQ5: 3.3 | FR5: 4 | FS5: 3 | FT5: 0.71 | FU5: 0.9 | FV5: 3 | FW5: 0.61 | FX5: 0.8 | FY5: 3
A6: 4 | B6: 20260428 | C6: 07:40 | D6: 0 | E6: 水手 | F6: 1分輸 | G6: 0.45 | H6: 0 | I6: 雙城 | J6: 0 | K6: 0.55 | L6: {=IFERROR(SUBSTITUTE(INDEX(正負盤!$6:$20, ROW(A3), MATCH(1, (MONTH(正負盤!$4:$4)=MONTH(DATE(LEFT($A$1,4),MID($A$1,5,2),RIGHT($A$1,2))-10))*(DAY(正負盤!$4:$4)=DAY(DATE(LEFT($A$1,4),MID($A$1,5,2),RIGHT($A$1,2))-10)), 0)), 0, "-"), "")} -> O | M6: {=IFERROR(SUBSTITUTE(INDEX(正負盤!$6:$20, ROW(A3), MATCH(1, (MONTH(正負盤!$4:$4)=MONTH(DATE(LEFT($A$1,4),MID($A$1,5,2),RIGHT($A$1,2))-9))*(DAY(正負盤!$4:$4)=DAY(DATE(LEFT($A$1,4),MID($A$1,5,2),RIGHT($A$1,2))-9)), 0)), 0, "-"), "")} -> X | N6: {=IFERROR(SUBSTITUTE(INDEX(正負盤!$6:$20, ROW(A3), MATCH(1, (MONTH(正負盤!$4:$4)=MONTH(DATE(LEFT($A$1,4),MID($A$1,5,2),RIGHT($A$1,2))-8))*(DAY(正負盤!$4:$4)=DAY(DATE(LEFT($A$1,4),MID($A$1,5,2),RIGHT($A$1,2))-8)), 0)), 0, "-"), "")} -> O | O6: {=IFERROR(SUBSTITUTE(INDEX(正負盤!$6:$20, ROW(A3), MATCH(1, (MONTH(正負盤!$4:$4)=MONTH(DATE(LEFT($A$1,4),MID($A$1,5,2),RIGHT($A$1,2))-7))*(DAY(正負盤!$4:$4)=DAY(DATE(LEFT($A$1,4),MID($A$1,5,2),RIGHT($A$1,2))-7)), 0)), 0, "-"), "")} -> X | P6: {=IFERROR(SUBSTITUTE(INDEX(正負盤!$6:$20, ROW(A3), MATCH(1, (MONTH(正負盤!$4:$4)=MONTH(DATE(LEFT($A$1,4),MID($A$1,5,2),RIGHT($A$1,2))-6))*(DAY(正負盤!$4:$4)=DAY(DATE(LEFT($A$1,4),MID($A$1,5,2),RIGHT($A$1,2))-6)), 0)), 0, "-"), "")} -> X | Q6: {=IFERROR(SUBSTITUTE(INDEX(正負盤!$6:$20, ROW(A3), MATCH(1, (MONTH(正負盤!$4:$4)=MONTH(DATE(LEFT($A$1,4),MID($A$1,5,2),RIGHT($A$1,2))-5))*(DAY(正負盤!$4:$4)=DAY(DATE(LEFT($A$1,4),MID($A$1,5,2),RIGHT($A$1,2))-5)), 0)), 0, "-"), "")} | R6: {=IFERROR(SUBSTITUTE(INDEX(正負盤!$6:$20, ROW(A3), MATCH(1, (MONTH(正負盤!$4:$4)=MONTH(DATE(LEFT($A$1,4),MID($A$1,5,2),RIGHT($A$1,2))-4))*(DAY(正負盤!$4:$4)=DAY(DATE(LEFT($A$1,4),MID($A$1,5,2),RIGHT($A$1,2))-4)), 0)), 0, "-"), "")} -> X | S6: {=IFERROR(SUBSTITUTE(INDEX(正負盤!$6:$20, ROW(A3), MATCH(1, (MONTH(正負盤!$4:$4)=MONTH(DATE(LEFT($A$1,4),MID($A$1,5,2),RIGHT($A$1,2))-3))*(DAY(正負盤!$4:$4)=DAY(DATE(LEFT($A$1,4),MID($A$1,5,2),RIGHT($A$1,2))-3)), 0)), 0, "-"), "")} -> O | T6: {=IFERROR(SUBSTITUTE(INDEX(正負盤!$6:$20, ROW(A3), MATCH(1, (MONTH(正負盤!$4:$4)=MONTH(DATE(LEFT($A$1,4),MID($A$1,5,2),RIGHT($A$1,2))-2))*(DAY(正負盤!$4:$4)=DAY(DATE(LEFT($A$1,4),MID($A$1,5,2),RIGHT($A$1,2))-2)), 0)), 0, "-"), "")} -> O | U6: {=IFERROR(SUBSTITUTE(INDEX(正負盤!$6:$20, ROW(A3), MATCH(1, (MONTH(正負盤!$4:$4)=MONTH(DATE(LEFT($A$1,4),MID($A$1,5,2),RIGHT($A$1,2))-1))*(DAY(正負盤!$4:$4)=DAY(DATE(LEFT($A$1,4),MID($A$1,5,2),RIGHT($A$1,2))-1)), 0)), 0, "-"), "")} -> O | V6: =C5 -> 07:07 | W6: =E5 -> 紅襪 | X6: {=_xlfn.LET(_xlpm.s,SUBSTITUTE(Y6,".",""),_xlpm.c,RIGHT(_xlpm.s,1),_xlpm.n,ROW(INDIRECT("1:"&LEN(_xlpm.s))),_xlpm.cnt,MAX(IF(RIGHT(_xlpm.s,_xlpm.n)=REPT(_xlpm.c,_xlpm.n),_xlpm.n,0)),IF(_xlpm.cnt>=2,_xlpm.cnt&"連"&_xlpm.c,"1"&_xlpm.c))} -> 2連O | Y6: {=INDEX(各隊正負!$F:$F, MATCH("*"&$W6&"*", 各隊正負!$A:$A, 0)+6)} -> O.O.X.X.O.X.X.X.O.O | AB6: {=INDEX(各隊正負!$F:$F, MATCH("*"&$W6&"*", 各隊正負!$A:$A, 0)+4)} -> W.W.L.L.W.L.L.L.W.W | AE6: {=_xlfn.LET(_xlpm.s,SUBSTITUTE(AB6,".",""),_xlpm.c,RIGHT(_xlpm.s,1),_xlpm.n,ROW(INDIRECT("1:"&LEN(_xlpm.s))),_xlpm.cnt,MAX(IF(RIGHT(_xlpm.s,_xlpm.n)=REPT(_xlpm.c,_xlpm.n),_xlpm.n,0)),_xlpm.suffix,IF(_xlpm.c="W","勝","敗"),IF(_xlpm.cnt>=2,_xlpm.cnt&"連"&_xlpm.suffix,"1"&_xlpm.suffix))} -> 2連勝 | AF6: =E5 -> 紅襪 | AG6: {=IFERROR(INDEX(各隊total!$B:$AB, MATCH($AF6, 各隊total!$A:$A, 0), COLUMN(A5)), "")} -> 28 | AH6: =CB11 -> 3.1 | AI6: =VLOOKUP(AH6*1, BV$15:BX$25, 3, TRUE) -> C+ | AJ6: =CC11 -> 2.7 | AK6: =VLOOKUP(AJ6*1, BY$15:CA$25, 3, TRUE) -> C+ | AL6: {=IFERROR(INDEX(各隊total!$C:$AB, MATCH($AF6, 各隊total!$A:$A, 0), COLUMN(A5)), "")} -> 936 | AM6: {=IFERROR(INDEX(各隊total!$D:$AB, MATCH($AF6, 各隊total!$A:$A, 0), COLUMN(A5)), "")} -> 117 | AN6: {=IFERROR(INDEX(各隊total!$E:$AB, MATCH($AF6, 各隊total!$A:$A, 0), COLUMN(A5)), "")} -> 218 | AO6: {=IFERROR(INDEX(各隊total!$F:$AB, MATCH($AF6, 各隊total!$A:$A, 0), COLUMN(A5)), "")} -> 50 | AP6: {=IFERROR(INDEX(各隊total!$G:$AB, MATCH($AF6, 各隊total!$A:$A, 0), COLUMN(A5)), "")} -> 4 | AQ6: {=IFERROR(INDEX(各隊total!$H:$AB, MATCH($AF6, 各隊total!$A:$A, 0), COLUMN(A5)), "")} -> 19 | AR6: {=IFERROR(INDEX(各隊total!$I:$AB, MATCH($AF6, 各隊total!$A:$A, 0), COLUMN(A5)), "")} -> 112 | AS6: {=IFERROR(INDEX(各隊total!$J:$AB, MATCH($AF6, 各隊total!$A:$A, 0), COLUMN(A5)), "")} -> 333 | AT6: {=IFERROR(INDEX(各隊total!$K:$AB, MATCH($AF6, 各隊total!$A:$A, 0), COLUMN(A5)), "")} -> 95 | AU6: {=IFERROR(INDEX(各隊total!$L:$AB, MATCH($AF6, 各隊total!$A:$A, 0), COLUMN(A5)), "")} -> 235 | AV6: {=IFERROR(INDEX(各隊total!$M:$AB, MATCH($AF6, 各隊total!$A:$A, 0), COLUMN(A5)), "")} -> 20 | AW6: {=IFERROR(INDEX(各隊total!$N:$AB, MATCH($AF6, 各隊total!$A:$A, 0), COLUMN(A5)), "")} -> .233 | AX6: {=IFERROR(INDEX(各隊total!$O:$AB, MATCH($AF6, 各隊total!$A:$A, 0), COLUMN(A5)), "")} -> .313 | AY6: {=IFERROR(INDEX(各隊total!$P:$AB, MATCH($AF6, 各隊total!$A:$A, 0), COLUMN(A5)), "")} -> .356 | AZ6: {=IFERROR(INDEX(各隊total!$Q:$AB, MATCH($AF6, 各隊total!$A:$A, 0), COLUMN(A5)), "")} -> .669 | BA6: {=IFERROR(INDEX(各隊total!$R:$AB, MATCH($AF6, 各隊total!$A:$A, 0), COLUMN(A5)), "")} -> 0 | BB6: {=IFERROR(INDEX(各隊total!$S:$AB, MATCH($AF6, 各隊total!$A:$A, 0), COLUMN(A5)), "")} -> 105.3 | BC6: {=IFERROR(INDEX(各隊total!$T:$AB, MATCH($AF6, 各隊total!$A:$A, 0), COLUMN(A5)), "")} -> 3.8 | BD6: {=IFERROR(INDEX(各隊total!$U:$AB, MATCH($AF6, 各隊total!$A:$A, 0), COLUMN(A5)), "")} -> .090 | BE6: {=IFERROR(INDEX(各隊total!$V:$AB, MATCH($AF6, 各隊total!$A:$A, 0), COLUMN(A5)), "")} -> 0.40 | BF6: {=IFERROR(INDEX(各隊total!$W:$AB, MATCH($AF6, 各隊total!$A:$A, 0), COLUMN(A5)), "")} -> .123 | BG6: {=IFERROR(INDEX(各隊total!$X:$AB, MATCH($AF6, 各隊total!$A:$A, 0), COLUMN(A5)), "")} -> .239 | BH6: {=IFERROR(INDEX(各隊total!$Y:$AB, MATCH($AF6, 各隊total!$A:$A, 0), COLUMN(A5)), "")} -> 3.81 | BI6: {=IFERROR(INDEX(各隊total!$Z:$AB, MATCH($AF6, 各隊total!$A:$A, 0), COLUMN(A5)), "")} -> 73 | BJ6: {=IFERROR(INDEX(各隊total!$AA:$AB, MATCH($AF6, 各隊total!$A:$A, 0), COLUMN(A5)), "")} -> 1054 | BK6: {=IFERROR(INDEX(各隊total!$AB:$AB, MATCH($AF6, 各隊total!$A:$A, 0), COLUMN(A5)), "")} -> 49.3 | BL6: {=IFERROR(INDEX(各隊total!$C:$AB, MATCH($AF6, 各隊total!$A:$A, 0), COLUMN(AA5)), "")} | BM6: 0.231 | BN6: 0.245 | BO6: 4 | BP6: 0.301 | BQ6: 0.315 | BR6: 4 | BS6: 0.396 | BT6: 0.42 | BU6: 4 | BV6: 4.3 | BW6: 4.5 | BX6: 4 | BY6: 4.1 | BZ6: 4.3 | CA6: 4 | CB6: =AF4 -> 紅雀 | CD6: =AG4 -> 27 | CE6: =AL4 -> 901 | CF6: =AM4 -> 125 | CG6: =AN4 -> 212 | CH6: =AO4 -> 35 | CI6: =AP4 -> 1 | CJ6: =AQ4 -> 34 | CK6: =AR4 -> 122 | CL6: =AS4 -> 351 | ... DD6: =BK4 -> 26.5 | DF6: =先發名單!I$2 -> J. Caminero | DG6: {=IFERROR(INDEX(球員狀態!$C$2:$C$5000, MATCH(1, (球員狀態!$A$2:$A$5000=$DF$1)*(ISNUMBER(SEARCH($DF6, 球員狀態!$B$2:$B$5000))), 0)), "")} | DJ6: {=IFERROR(INDEX(球員狀態!$F$2:$F$5000, MATCH(1, (球員狀態!$A$2:$A$5000=$DF$1)*(ISNUMBER(SEARCH($DF6, 球員狀態!$B$2:$B$5000))), 0)), "")} | DK6: {=IFERROR(INDEX(球員狀態!$G$2:$G$5000, MATCH(1, (球員狀態!$A$2:$A$5000=$DF$1)*(ISNUMBER(SEARCH($DF6, 球員狀態!$B$2:$B$5000))), 0)), "")} | DL6: {=IFERROR(INDEX(球員狀態!H$2:H$5000, MATCH(1, (球員狀態!$A$2:$A$5000=$DF$1)*(ISNUMBER(SEARCH($DF6, 球員狀態!$B$2:$B$5000))), 0)), "")} | DM6: {=IFERROR(INDEX(球員狀態!I$2:I$5000, MATCH(1, (球員狀態!$A$2:$A$5000=$DF$1)*(ISNUMBER(SEARCH($DF6, 球員狀態!$B$2:$B$5000))), 0)), "")} | DN6: {=IFERROR(INDEX(球員狀態!J$2:J$5000, MATCH(1, (球員狀態!$A$2:$A$5000=$DF$1)*(ISNUMBER(SEARCH($DF6, 球員狀態!$B$2:$B$5000))), 0)), "")} | DO6: {=IFERROR(INDEX(球員狀態!K$2:K$5000, MATCH(1, (球員狀態!$A$2:$A$5000=$DF$1)*(ISNUMBER(SEARCH($DF6, 球員狀態!$B$2:$B$5000))), 0)), "")} | DP6: {=IFERROR(INDEX(球員狀態!L$2:L$5000, MATCH(1, (球員狀態!$A$2:$A$5000=$DF$1)*(ISNUMBER(SEARCH($DF6, 球員狀態!$B$2:$B$5000))), 0)), "")} | DQ6: {=IFERROR(INDEX(球員狀態!M$2:M$5000, MATCH(1, (球員狀態!$A$2:$A$5000=$DF$1)*(ISNUMBER(SEARCH($DF6, 球員狀態!$B$2:$B$5000))), 0)), "")} | DR6: {=IFERROR(INDEX(球員狀態!N$2:N$5000, MATCH(1, (球員狀態!$A$2:$A$5000=$DF$1)*(ISNUMBER(SEARCH($DF6, 球員狀態!$B$2:$B$5000))), 0)), "")} | DS6: {=IFERROR(INDEX(球員狀態!O$2:O$5000, MATCH(1, (球員狀態!$A$2:$A$5000=$DF$1)*(ISNUMBER(SEARCH($DF6, 球員狀態!$B$2:$B$5000))), 0)), "")} | ... EF6: {=IFERROR(INDEX(球員狀態!AB$2:AB$5000, MATCH(1, (球員狀態!$A$2:$A$5000=$DF$1)*(ISNUMBER(SEARCH($DF6, 球員狀態!$B$2:$B$5000))), 0)), "")} | EI6: =先發名單!Q$2 -> A. Martinez | EJ6: {=IFERROR(INDEX(球員狀態!$C$2:$C$5000, MATCH(1, (球員狀態!$A$2:$A$5000=$EI$1)*(ISNUMBER(SEARCH($EI6, 球員狀態!$B$2:$B$5000))), 0)), "")} | EM6: {=IFERROR(INDEX(球員狀態!F$2:F$5000, MATCH(1, (球員狀態!$A$2:$A$5000=$EI$1)*(ISNUMBER(SEARCH($EI6, 球員狀態!$B$2:$B$5000))), 0)), "")} | EN6: {=IFERROR(INDEX(球員狀態!G$2:G$5000, MATCH(1, (球員狀態!$A$2:$A$5000=$EI$1)*(ISNUMBER(SEARCH($EI6, 球員狀態!$B$2:$B$5000))), 0)), "")} | EO6: {=IFERROR(INDEX(球員狀態!H$2:H$5000, MATCH(1, (球員狀態!$A$2:$A$5000=$EI$1)*(ISNUMBER(SEARCH($EI6, 球員狀態!$B$2:$B$5000))), 0)), "")} | EP6: {=IFERROR(INDEX(球員狀態!I$2:I$5000, MATCH(1, (球員狀態!$A$2:$A$5000=$EI$1)*(ISNUMBER(SEARCH($EI6, 球員狀態!$B$2:$B$5000))), 0)), "")} | EQ6: {=IFERROR(INDEX(球員狀態!J$2:J$5000, MATCH(1, (球員狀態!$A$2:$A$5000=$EI$1)*(ISNUMBER(SEARCH($EI6, 球員狀態!$B$2:$B$5000))), 0)), "")} | ER6: {=IFERROR(INDEX(球員狀態!K$2:K$5000, MATCH(1, (球員狀態!$A$2:$A$5000=$EI$1)*(ISNUMBER(SEARCH($EI6, 球員狀態!$B$2:$B$5000))), 0)), "")} | ES6: {=IFERROR(INDEX(球員狀態!L$2:L$5000, MATCH(1, (球員狀態!$A$2:$A$5000=$EI$1)*(ISNUMBER(SEARCH($EI6, 球員狀態!$B$2:$B$5000))), 0)), "")} | ET6: {=IFERROR(INDEX(球員狀態!M$2:M$5000, MATCH(1, (球員狀態!$A$2:$A$5000=$EI$1)*(ISNUMBER(SEARCH($EI6, 球員狀態!$B$2:$B$5000))), 0)), "")} | ... FI6: {=IFERROR(INDEX(球員狀態!AB$2:AB$5000, MATCH(1, (球員狀態!$A$2:$A$5000=$EI$1)*(ISNUMBER(SEARCH($EI6, 球員狀態!$B$2:$B$5000))), 0)), "")} | FK6: 10.1 | FL6: 12 | FM6: 4 | FN6: 4.6 | FO6: 5.5 | FP6: 4 | FQ6: 4.1 | FR6: 5 | FS6: 4 | FT6: 0.91 | FU6: 1.1 | FV6: 4 | FW6: 0.81 | FX6: 1 | FY6: 4
